Workbook

Sheet CN
C4: Goverment Sector | D4: Components Goverment Sector | H4: Corporate Sector | I4: Components Corporate Sector | M4: Household Sector | N4: Components Household Sector | V4: Total Economy | AB4: Capital Shares
N5: Housing | Q5: Self-employment | V5: Compen-sation of employees | W5: Mixed- income and OS | X5: Gross Operating Surplus | Y5: Gross Mixed Income | Z5: CFC | AA5: Production Taxes | AG5: Checks
A6: Notes | R6: assume 10 household value added are paid direclty as wages%
A7: iso | B7: year | C7: gvago | D7: ceugo | E7: gsrgo | F7: nsrgo | G7: cfcgo | H7: gvaco | I7: ceuco | J7: gsrco | K7: nsrco | L7: cfcco | M7: gvahn | N7: gsrhn | O7: nsrhn | P7: ccshn | Q7: gvmhn | R7: ceuhn | S7: gmxhn | T7: nmxhn | U7: ccmhn | V7: comhn | Y7: gmxhn | Z7: confc | AA7: ptxgo | AB7: cshare | AC7: cshare_gross | AD7: cshare_corp | AE7: chare_corp_gross | AF7: check_sector | AG7: check_total
A8: CN | B8: 1979 | G8: ='AP2'!DK39 / ('AP2'!CG39*'AP2'!T39) -> 0.0036624803 | N8: =O8+P8 -> 0.015508286 | O8: ='AP2'!EE39 / ('AP2'!CG39*'AP2'!T39) -> 0.0056487486 | P8: ='AP2'!EB39 / ('AP2'!CG39*'AP2'!T39) -> 0.0098595373 | Q8: =('AP2'!EF39+'AP2'!EM39- 'AP2'!EQ39) / ('AP2'!CG39*'AP2'!T39) -> 0.27519609 | R8: =0.1*Q8 -> 0.027519609 | S8: =Q8-R8 -> 0.24767648 | T8: =S8-U8 -> 0.24384157 | U8: =('AP2'!EN39+'AP2'!EG39 ) / ('AP2'!CG39*'AP2'!T39) -> 0.0038349118
A9: CN | B9: 1980 | G9: ='AP2'!DK40 / ('AP2'!CG40*'AP2'!T40) -> 0.0036923717 | M9: =N9+Q9 -> 0.28078732 | N9: =O9+P9 -> 0.016103579 | O9: ='AP2'!EE40 / ('AP2'!CG40*'AP2'!T40) -> 0.0057921339 | P9: ='AP2'!EB40 / ('AP2'!CG40*'AP2'!T40) -> 0.010311445 | Q9: =('AP2'!EF40+'AP2'!EM40 -'AP2'!EQ40 ) / ('AP2'!CG40*'AP2'!T40) -> 0.26468374 | R9: =0.1*Q9 -> 0.026468374 | S9: =Q9-R9 -> 0.23821536 | T9: =S9-U9 -> 0.23328627 | U9: =('AP2'!EN40+'AP2'!EG40 ) / ('AP2'!CG40*'AP2'!T40) -> 0.0049290913
A10: CN | B10: 1981 | G10: ='AP2'!DK41 / ('AP2'!CG41*'AP2'!T41) -> 0.0036848852 | M10: =N10+Q10 -> 0.29258466 | N10: =O10+P10 -> 0.017058512 | O10: ='AP2'!EE41 / ('AP2'!CG41*'AP2'!T41) -> 0.0063348442 | P10: ='AP2'!EB41 / ('AP2'!CG41*'AP2'!T41) -> 0.010723668 | Q10: =('AP2'!EF41+'AP2'!EM41 -'AP2'!EQ41 ) / ('AP2'!CG41*'AP2'!T41) -> 0.27552614 | R10: =0.1*Q10 -> 0.027552614 | S10: =Q10-R10 -> 0.24797353 | T10: =S10-U10 -> 0.2421072 | U10: =('AP2'!EN41+'AP2'!EG41 ) / ('AP2'!CG41*'AP2'!T41) -> 0.0058663312
A11: CN | B11: 1982 | G11: ='AP2'!DK42 / ('AP2'!CG42*'AP2'!T42) -> 0.0040662954 | M11: =N11+Q11 -> 0.29898435 | N11: =O11+P11 -> 0.018013226 | O11: ='AP2'!EE42 / ('AP2'!CG42*'AP2'!T42) -> 0.0070109978 | P11: ='AP2'!EB42 / ('AP2'!CG42*'AP2'!T42) -> 0.011002228 | Q11: =('AP2'!EF42+'AP2'!EM42 -'AP2'!EQ42 ) / ('AP2'!CG42*'AP2'!T42) -> 0.28097112 | R11: =0.1*Q11 -> 0.028097112 | S11: =Q11-R11 -> 0.25287401 | T11: =S11-U11 -> 0.24641672 | U11: =('AP2'!EN42+'AP2'!EG42 ) / ('AP2'!CG42*'AP2'!T42) -> 0.0064572882
A12: CN | B12: 1983 | G12: ='AP2'!DK43 / ('AP2'!CG43*'AP2'!T43) -> 0.0045768806 | M12: =N12+Q12 -> 0.30078775 | N12: =O12+P12 -> 0.020232024 | O12: ='AP2'!EE43 / ('AP2'!CG43*'AP2'!T43) -> 0.0080631785 | P12: ='AP2'!EB43 / ('AP2'!CG43*'AP2'!T43) -> 0.012168846 | Q12: =('AP2'!EF43+'AP2'!EM43 -'AP2'!EQ43 ) / ('AP2'!CG43*'AP2'!T43) -> 0.28055573 | R12: =0.1*Q12 -> 0.028055573 | S12: =Q12-R12 -> 0.25250015 | T12: =S12-U12 -> 0.24569691 | U12: =('AP2'!EN43+'AP2'!EG43 ) / ('AP2'!CG43*'AP2'!T43) -> 0.0068032418
A13: CN | B13: 1984 | G13: ='AP2'!DK44 / ('AP2'!CG44*'AP2'!T44) -> 0.0048054409 | M13: =N13+Q13 -> 0.29861188 | N13: =O13+P13 -> 0.021776874 | O13: ='AP2'!EE44 / ('AP2'!CG44*'AP2'!T44) -> 0.0086676508 | P13: ='AP2'!EB44 / ('AP2'!CG44*'AP2'!T44) -> 0.013109223 | Q13: =('AP2'!EF44+'AP2'!EM44 -'AP2'!EQ44 ) / ('AP2'!CG44*'AP2'!T44) -> 0.276835 | R13: =0.1*Q13 -> 0.0276835 | S13: =Q13-R13 -> 0.2491515 | T13: =S13-U13 -> 0.24261141 | U13: =('AP2'!EN44+'AP2'!EG44 ) / ('AP2'!CG44*'AP2'!T44) -> 0.0065400953
A14: CN | B14: 1985 | G14: ='AP2'!DK45 / ('AP2'!CG45*'AP2'!T45) -> 0.0051582897 | M14: =N14+Q14 -> 0.27052188 | N14: =O14+P14 -> 0.022161232 | O14: ='AP2'!EE45 / ('AP2'!CG45*'AP2'!T45) -> 0.0089624825 | P14: ='AP2'!EB45 / ('AP2'!CG45*'AP2'!T45) -> 0.01319875 | Q14: =('AP2'!EF45+'AP2'!EM45 -'AP2'!EQ45 ) / ('AP2'!CG45*'AP2'!T45) -> 0.24836065 | R14: =0.1*Q14 -> 0.024836065 | S14: =Q14-R14 -> 0.22352458 | T14: =S14-U14 -> 0.21739632 | U14: =('AP2'!EN45+'AP2'!EG45 ) / ('AP2'!CG45*'AP2'!T45) -> 0.0061282641
A15: CN | B15: 1986 | G15: ='AP2'!DK46 / ('AP2'!CG46*'AP2'!T46) -> 0.0060251713 | M15: =N15+Q15 -> 0.25583398 | N15: =O15+P15 -> 0.023497451 | O15: ='AP2'!EE46 / ('AP2'!CG46*'AP2'!T46) -> 0.010000367 | P15: ='AP2'!EB46 / ('AP2'!CG46*'AP2'!T46) -> 0.013497085 | Q15: =('AP2'!EF46+'AP2'!EM46 -'AP2'!EQ46 ) / ('AP2'!CG46*'AP2'!T46) -> 0.23233653 | R15: =0.1*Q15 -> 0.023233653 | S15: =Q15-R15 -> 0.20910288 | T15: =S15-U15 -> 0.20278259 | U15: =('AP2'!EN46+'AP2'!EG46 ) / ('AP2'!CG46*'AP2'!T46) -> 0.0063202883
A16: CN | B16: 1987 | G16: ='AP2'!DK47 / ('AP2'!CG47*'AP2'!T47) -> 0.0075773106 | M16: =N16+Q16 -> 0.25388295 | N16: =O16+P16 -> 0.022578108 | O16: ='AP2'!EE47 / ('AP2'!CG47*'AP2'!T47) -> 0.008741728 | P16: ='AP2'!EB47 / ('AP2'!CG47*'AP2'!T47) -> 0.01383638 | Q16: =('AP2'!EF47+'AP2'!EM47 -'AP2'!EQ47 ) / ('AP2'!CG47*'AP2'!T47) -> 0.23130485 | R16: =0.1*Q16 -> 0.023130485 | S16: =Q16-R16 -> 0.20817436 | T16: =S16-U16 -> 0.2022511 | U16: =('AP2'!EN47+'AP2'!EG47 ) / ('AP2'!CG47*'AP2'!T47) -> 0.0059232588
A17: CN | B17: 1988 | G17: ='AP2'!DK48 / ('AP2'!CG48*'AP2'!T48) -> 0.0065405274 | M17: =N17+Q17 -> 0.24200728 | N17: =O17+P17 -> 0.021421775 | O17: ='AP2'!EE48 / ('AP2'!CG48*'AP2'!T48) -> 0.0088672255 | P17: ='AP2'!EB48 / ('AP2'!CG48*'AP2'!T48) -> 0.01255455 | Q17: =('AP2'!EF48+'AP2'!EM48 -'AP2'!EQ48 ) / ('AP2'!CG48*'AP2'!T48) -> 0.22058551 | R17: =0.1*Q17 -> 0.022058551 | S17: =Q17-R17 -> 0.19852696 | T17: =S17-U17 -> 0.19299326 | U17: =('AP2'!EN48+'AP2'!EG48 ) / ('AP2'!CG48*'AP2'!T48) -> 0.0055337013
A18: CN | B18: 1989 | G18: ='AP2'!DK49 / ('AP2'!CG49*'AP2'!T49) -> 0.0077611901 | M18: =N18+Q18 -> 0.23905334 | N18: =O18+P18 -> 0.0229704 | O18: ='AP2'!EE49 / ('AP2'!CG49*'AP2'!T49) -> 0.0092948888 | P18: ='AP2'!EB49 / ('AP2'!CG49*'AP2'!T49) -> 0.013675511 | Q18: =('AP2'!EF49+'AP2'!EM49 -'AP2'!EQ49 ) / ('AP2'!CG49*'AP2'!T49) -> 0.21608294 | R18: =0.1*Q18 -> 0.021608294 | S18: =Q18-R18 -> 0.19447464 | T18: =S18-U18 -> 0.18919515 | U18: =('AP2'!EN49+'AP2'!EG49 ) / ('AP2'!CG49*'AP2'!T49) -> 0.0052794876
A19: CN | B19: 1990 | G19: ='AP2'!DK50 / ('AP2'!CG50*'AP2'!T50) -> 0.0079275667 | M19: =N19+Q19 -> 0.25417556 | N19: =O19+P19 -> 0.025526462 | O19: ='AP2'!EE50 / ('AP2'!CG50*'AP2'!T50) -> 0.010543657 | P19: ='AP2'!EB50 / ('AP2'!CG50*'AP2'!T50) -> 0.014982805 | Q19: =('AP2'!EF50+'AP2'!EM50 -'AP2'!EQ50 ) / ('AP2'!CG50*'AP2'!T50) -> 0.2286491 | R19: =0.1*Q19 -> 0.02286491 | S19: =Q19-R19 -> 0.20578419 | T19: =S19-U19 -> 0.20129289 | U19: =('AP2'!EN50+'AP2'!EG50 ) / ('AP2'!CG50*'AP2'!T50) -> 0.0044912987
A20: CN | B20: 1991 | G20: ='AP2'!DK51 / ('AP2'!CG51*'AP2'!T51) -> 0.00779925 | M20: =N20+Q20 -> 0.23431733 | N20: =O20+P20 -> 0.027879948 | O20: ='AP2'!EE51 / ('AP2'!CG51*'AP2'!T51) -> 0.011420046 | P20: ='AP2'!EB51 / ('AP2'!CG51*'AP2'!T51) -> 0.016459902 | Q20: =('AP2'!EF51+'AP2'!EM51 -'AP2'!EQ51 ) / ('AP2'!CG51*'AP2'!T51) -> 0.20643738 | R20: =0.1*Q20 -> 0.020643738 | S20: =Q20-R20 -> 0.18579364 | T20: =S20-U20 -> 0.18196429 | U20: =('AP2'!EN51+'AP2'!EG51 ) / ('AP2'!CG51*'AP2'!T51) -> 0.0038293498
A21: CN | B21: 1992 | C21: =D21+E21 -> 0.11568858 | D21: ='AP2'!FZ52 / ('AP2'!CG52*'AP2'!T52) -> 0.080993295 | E21: =F21+G21 -> 0.034695284 | F21: ='AP2'!GA52 / ('AP2'!CG52*'AP2'!T52) -> 0.026723001 | G21: ='AP2'!DK52 / ('AP2'!CG52*'AP2'!T52) -> 0.0079722828 | H21: =I21+J21 -> 0.49159728 | I21: ='AP2'!FF52 / ('AP2'!CG52*'AP2'!T52) -> 0.27536523 | J21: =K21+L21 -> 0.21623205 | K21: ='AP2'!FG52 / ('AP2'!CG52*'AP2'!T52) -> 0.12841636 | L21: ='AP2'!FB52 / ('AP2'!CG52*'AP2'!T52) -> 0.087815697 | M21: =N21+Q21 -> 0.2809102 | N21: =O21+P21 -> 0.027938843 | O21: ='AP2'!EE52 / ('AP2'!CG52*'AP2'!T52) -> 0.012460042 | P21: ='AP2'!EB52 / ('AP2'!CG52*'AP2'!T52) -> 0.015478801 | Q21: =('AP2'!EF52+'AP2'!EM52 -'AP2'!EQ52 ) / ('AP2'!CG52*'AP2'!T52) -> 0.25297136 | R21: =0.1*Q21 -> 0.025297136 | S21: =Q21-R21 -> 0.22767422 | T21: =S21-U21 -> 0.22336417 | U21: =('AP2'!EN52+'AP2'!EG52 ) / ('AP2'!CG52*'AP2'!T52) -> 0.0043100469
A22: CN | B22: 1993 | C22: =D22+E22 -> 0.10117473 | D22: ='AP2'!FZ53 / ('AP2'!CG53*'AP2'!T53) -> 0.070994142 | E22: =F22+G22 -> 0.030180588 | F22: ='AP2'!GA53 / ('AP2'!CG53*'AP2'!T53) -> 0.021054459 | G22: ='AP2'!DK53 / ('AP2'!CG53*'AP2'!T53) -> 0.009126129 | H22: =I22+J22 -> 0.51399507 | I22: ='AP2'!FF53 / ('AP2'!CG53*'AP2'!T53) -> 0.26436059 | J22: =K22+L22 -> 0.24963448 | K22: ='AP2'!FG53 / ('AP2'!CG53*'AP2'!T53) -> 0.16440985 | L22: ='AP2'!FB53 / ('AP2'!CG53*'AP2'!T53) -> 0.085224633 | M22: =N22+Q22 -> 0.25047375 | N22: =O22+P22 -> 0.03053094 | O22: ='AP2'!EE53 / ('AP2'!CG53*'AP2'!T53) -> 0.013352948 | P22: ='AP2'!EB53 / ('AP2'!CG53*'AP2'!T53) -> 0.017177991 | Q22: =('AP2'!EF53+'AP2'!EM53 -'AP2'!EQ53 ) / ('AP2'!CG53*'AP2'!T53) -> 0.21994281 | R22: =0.1*Q22 -> 0.021994281 | S22: =Q22-R22 -> 0.19794853 | T22: =S22-U22 -> 0.19315782 | U22: =('AP2'!EN53+'AP2'!EG53 ) / ('AP2'!CG53*'AP2'!T53) -> 0.0047907052 | Z22: =U22+P22+L22+G22 -> 0.11631946 | AA22: ='A32'!I25*'A30'!N23 -> 0.096423849 | AB22: =(F21+K21+O21+0.3*T21)/(1-AA22) -> 0.25964458 | AC22: =(E21+J21+N21+U21+0.3*T21)/(1-AA22) -> 0.38755503 | AF22: =M22+H22+C22+AA22 -> 0.96206739
A23: CN | B23: 1994 | C23: =D23+E23 -> 0.088527509 | D23: ='AP2'!FZ54 / ('AP2'!CG54*'AP2'!T54) -> 0.061406673 | E23: =F23+G23 -> 0.027120836 | F23: ='AP2'!GA54 / ('AP2'!CG54*'AP2'!T54) -> 0.018684626 | G23: ='AP2'!DK54 / ('AP2'!CG54*'AP2'!T54) -> 0.0084362107 | H23: =I23+J23 -> 0.51969386 | I23: ='AP2'!FF54 / ('AP2'!CG54*'AP2'!T54) -> 0.28332107 | J23: =K23+L23 -> 0.23637278 | K23: ='AP2'!FG54 / ('AP2'!CG54*'AP2'!T54) -> 0.1466658 | L23: ='AP2'!FB54 / ('AP2'!CG54*'AP2'!T54) -> 0.08970698 | M23: =N23+Q23 -> 0.26871189 | N23: =O23+P23 -> 0.029568789 | O23: ='AP2'!EE54 / ('AP2'!CG54*'AP2'!T54) -> 0.012476672 | P23: ='AP2'!EB54 / ('AP2'!CG54*'AP2'!T54) -> 0.017092117 | Q23: =('AP2'!EF54+'AP2'!EM54 -'AP2'!EQ54 ) / ('AP2'!CG54*'AP2'!T54) -> 0.2391431 | R23: =0.1*Q23 -> 0.02391431 | S23: =Q23-R23 -> 0.21522879 | T23: =S23-U23 -> 0.21074313 | U23: =('AP2'!EN54+'AP2'!EG54 ) / ('AP2'!CG54*'AP2'!T54) -> 0.0044856641 | Z23: =U23+P23+L23+G23 -> 0.11972097 | AA23: ='A32'!I26*'A30'!N24 -> 0.087372938 | AB23: =(F22+K22+O22+0.3*T22)/(1-AA23) -> 0.28134669 | AC23: =(E22+J22+N22+U22+0.3*T22)/(1-AA23) -> 0.40880232 | AF23: =M23+H23+C23+AA23 -> 0.96430619
A24: CN | B24: 1995 | C24: =D24+E24 -> 0.079183963 | D24: ='AP2'!FZ55 / ('AP2'!CG55*'AP2'!T55) -> 0.057396622 | E24: =F24+G24 -> 0.021787341 | F24: ='AP2'!GA55 / ('AP2'!CG55*'AP2'!T55) -> 0.015542845 | G24: ='AP2'!DK55 / ('AP2'!CG55*'AP2'!T55) -> 0.0062444952 | H24: =I24+J24 -> 0.54271776 | I24: ='AP2'!FF55 / ('AP2'!CG55*'AP2'!T55) -> 0.28879415 | J24: =K24+L24 -> 0.25392361 | K24: ='AP2'!FG55 / ('AP2'!CG55*'AP2'!T55) -> 0.15914725 | L24: ='AP2'!FB55 / ('AP2'!CG55*'AP2'!T55) -> 0.094776364 | M24: =N24+Q24 -> 0.26355314 | N24: =O24+P24 -> 0.031290224 | O24: ='AP2'!EE55 / ('AP2'!CG55*'AP2'!T55) -> 0.013735746 | P24: ='AP2'!EB55 / ('AP2'!CG55*'AP2'!T55) -> 0.017554478 | Q24: =('AP2'!EF55+'AP2'!EM55 -'AP2'!EQ55 ) / ('AP2'!CG55*'AP2'!T55) -> 0.23226291 | R24: =0.1*Q24 -> 0.023226291 | S24: =Q24-R24 -> 0.20903662 | T24: =S24-U24 -> 0.20460955 | U24: =('AP2'!EN55+'AP2'!EG55 ) / ('AP2'!CG55*'AP2'!T55) -> 0.0044270757 | Z24: =U24+P24+L24+G24 -> 0.12300241 | AA24: ='A32'!I27*'A30'!N25 -> 0.080216174 | AB24: =(F23+K23+O23+0.3*T23)/(1-AA24) -> 0.26207249 | AC24: =(E23+J23+N23+U23+0.3*T23)/(1-AA24) -> 0.39223457 | AF24: =M24+H24+C24+AA24 -> 0.96567104
A25: CN | B25: 1996 | C25: =D25+E25 -> 0.073378048 | D25: ='AP2'!FZ56 / ('AP2'!CG56*'AP2'!T56) -> 0.047771304 | E25: =F25+G25 -> 0.025606744 | F25: ='AP2'!GA56 / ('AP2'!CG56*'AP2'!T56) -> 0.020395672 | G25: ='AP2'!DK56 / ('AP2'!CG56*'AP2'!T56) -> 0.0052110715 | H25: =I25+J25 -> 0.5317481 | I25: ='AP2'!FF56 / ('AP2'!CG56*'AP2'!T56) -> 0.30155183 | J25: =K25+L25 -> 0.23019626 | K25: ='AP2'!FG56 / ('AP2'!CG56*'AP2'!T56) -> 0.13232161 | L25: ='AP2'!FB56 / ('AP2'!CG56*'AP2'!T56) -> 0.097874648 | M25: =N25+Q25 -> 0.28048523 | N25: =O25+P25 -> 0.035977908 | O25: ='AP2'!EE56 / ('AP2'!CG56*'AP2'!T56) -> 0.016577585 | P25: ='AP2'!EB56 / ('AP2'!CG56*'AP2'!T56) -> 0.019400323 | Q25: =('AP2'!EF56+'AP2'!EM56 -'AP2'!EQ56 ) / ('AP2'!CG56*'AP2'!T56) -> 0.24450732 | R25: =0.1*Q25 -> 0.024450732 | S25: =Q25-R25 -> 0.22005659 | T25: =S25-U25 -> 0.21571134 | U25: =('AP2'!EN56+'AP2'!EG56 ) / ('AP2'!CG56*'AP2'!T56) -> 0.0043452532 | Z25: =U25+P25+L25+G25 -> 0.1268313 | AA25: ='A32'!I28*'A30'!N26 -> 0.078337458 | AB25: =(F24+K24+O24+0.3*T24)/(1-AA25) -> 0.2710414 | AC25: =(E24+J24+N24+U24+0.3*T24)/(1-AA25) -> 0.4044985 | AF25: =M25+H25+C25+AA25 -> 0.96394883
A26: CN | B26: 1997 | C26: =D26+E26 -> 0.074346872 | D26: ='AP2'!FZ57 / ('AP2'!CG57*'AP2'!T57) -> 0.050731972 | E26: =F26+G26 -> 0.0236149 | F26: ='AP2'!GA57 / ('AP2'!CG57*'AP2'!T57) -> 0.018687256 | G26: ='AP2'!DK57 / ('AP2'!CG57*'AP2'!T57) -> 0.0049276437 | H26: =I26+J26 -> 0.52295878 | I26: ='AP2'!FF57 / ('AP2'!CG57*'AP2'!T57) -> 0.30301067 | J26: =K26+L26 -> 0.21994811 | K26: ='AP2'!FG57 / ('AP2'!CG57*'AP2'!T57) -> 0.12067687 | L26: ='AP2'!FB57 / ('AP2'!CG57*'AP2'!T57) -> 0.099271244 | M26: =N26+Q26 -> 0.28778114 | N26: =O26+P26 -> 0.042751265 | O26: ='AP2'!EE57 / ('AP2'!CG57*'AP2'!T57) -> 0.020188693 | P26: ='AP2'!EB57 / ('AP2'!CG57*'AP2'!T57) -> 0.022562572 | Q26: =('AP2'!EF57+'AP2'!EM57 -'AP2'!EQ57 ) / ('AP2'!CG57*'AP2'!T57) -> 0.24502988 | R26: =0.1*Q26 -> 0.024502988 | S26: =Q26-R26 -> 0.22052689 | T26: =S26-U26 -> 0.21540878 | U26: =('AP2'!EN57+'AP2'!EG57 ) / ('AP2'!CG57*'AP2'!T57) -> 0.0051181043 | Z26: =U26+P26+L26+G26 -> 0.13187956 | AA26: ='A32'!I29*'A30'!N27 -> 0.085800691 | AB26: =(F25+K25+O25+0.3*T25)/(1-AA26) -> 0.25597074 | AC26: =(E25+J25+N25+U25+0.3*T25)/(1-AA26) -> 0.39470558 | AF26: =M26+H26+C26+AA26 -> 0.97088749
A27: CN | B27: 1998 | C27: =D27+E27 -> 0.080606795 | D27: ='AP2'!FZ58 / ('AP2'!CG58*'AP2'!T58) -> 0.059670443 | E27: =F27+G27 -> 0.020936352 | F27: ='AP2'!GA58 / ('AP2'!CG58*'AP2'!T58) -> 0.016380432 | G27: ='AP2'!DK58 / ('AP2'!CG58*'AP2'!T58) -> 0.00455592 | H27: =I27+J27 -> 0.50602584 | I27: ='AP2'!FF58 / ('AP2'!CG58*'AP2'!T58) -> 0.28731768 | J27: =K27+L27 -> 0.21870817 | K27: ='AP2'!FG58 / ('AP2'!CG58*'AP2'!T58) -> 0.11412523 | L27: ='AP2'!FB58 / ('AP2'!CG58*'AP2'!T58) -> 0.10458293 | M27: =N27+Q27 -> 0.30025608 | N27: =O27+P27 -> 0.048564321 | O27: ='AP2'!EE58 / ('AP2'!CG58*'AP2'!T58) -> 0.023232131 | P27: ='AP2'!EB58 / ('AP2'!CG58*'AP2'!T58) -> 0.02533219 | Q27: =('AP2'!EF58+'AP2'!EM58 -'AP2'!EQ58 ) / ('AP2'!CG58*'AP2'!T58) -> 0.25169176 | R27: =0.1*Q27 -> 0.025169176 | S27: =Q27-R27 -> 0.22652258 | T27: =S27-U27 -> 0.22087555 | U27: =('AP2'!EN58+'AP2'!EG58 ) / ('AP2'!CG58*'AP2'!T58) -> 0.0056470333 | Z27: =U27+P27+L27+G27 -> 0.14011807 | AA27: ='A32'!I30*'A30'!N28 -> 0.091507707 | AB27: =(F26+K26+O26+0.3*T26)/(1-AA27) -> 0.24675548 | AC27: =(E26+J26+N26+U26+0.3*T26)/(1-AA27) -> 0.39191859 | AF27: =M27+H27+C27+AA27 -> 0.97839643
A28: CN | B28: 1999 | C28: =D28+E28 -> 0.082203605 | D28: ='AP2'!FZ59 / ('AP2'!CG59*'AP2'!T59) -> 0.06517629 | E28: =F28+G28 -> 0.017027315 | F28: ='AP2'!GA59 / ('AP2'!CG59*'AP2'!T59) -> 0.012634744 | G28: ='AP2'!DK59 / ('AP2'!CG59*'AP2'!T59) -> 0.0043925712 | H28: =I28+J28 -> 0.49488925 | I28: ='AP2'!FF59 / ('AP2'!CG59*'AP2'!T59) -> 0.2733722 | J28: =K28+L28 -> 0.22151706 | K28: ='AP2'!FG59 / ('AP2'!CG59*'AP2'!T59) -> 0.11173438 | L28: ='AP2'!FB59 / ('AP2'!CG59*'AP2'!T59) -> 0.10978268 | M28: =N28+Q28 -> 0.30736792 | N28: =O28+P28 -> 0.05308609 | O28: ='AP2'!EE59 / ('AP2'!CG59*'AP2'!T59) -> 0.025116382 | P28: ='AP2'!EB59 / ('AP2'!CG59*'AP2'!T59) -> 0.027969707 | Q28: =('AP2'!EF59+'AP2'!EM59 -'AP2'!EQ59 ) / ('AP2'!CG59*'AP2'!T59) -> 0.25428183 | R28: =0.1*Q28 -> 0.025428183 | S28: =Q28-R28 -> 0.22885365 | T28: =S28-U28 -> 0.22246734 | U28: =('AP2'!EN59+'AP2'!EG59 ) / ('AP2'!CG59*'AP2'!T59) -> 0.0063863087 | Z28: =U28+P28+L28+G28 -> 0.14853127 | AA28: ='A32'!I31*'A30'!N29 -> 0.10176025 | AB28: =(F27+K27+O27+0.3*T27)/(1-AA28) -> 0.24492399 | AC28: =(E27+J27+N27+U27+0.3*T27)/(1-AA28) -> 0.40091583 | AF28: =M28+H28+C28+AA28 -> 0.98622103
A29: CN | B29: 2000 | C29: =D29+E29 -> 0.079842542 | D29: ='AP2'!FZ60 / ('AP2'!CG60*'AP2'!T60) -> 0.062805845 | E29: =F29+G29 -> 0.017036696 | F29: ='AP2'!GA60 / ('AP2'!CG60*'AP2'!T60) -> 0.013333078 | G29: ='AP2'!DK60 / ('AP2'!CG60*'AP2'!T60) -> 0.0037036181 | H29: =I29+J29 -> 0.47920202 | I29: ='AP2'!FF60 / ('AP2'!CG60*'AP2'!T60) -> 0.2638811 | J29: =K29+L29 -> 0.21532092 | K29: ='AP2'!FG60 / ('AP2'!CG60*'AP2'!T60) -> 0.098603443 | L29: ='AP2'!FB60 / ('AP2'!CG60*'AP2'!T60) -> 0.11671748 | M29: =N29+Q29 -> 0.32867833 | N29: =O29+P29 -> 0.060615999 | O29: ='AP2'!EE60 / ('AP2'!CG60*'AP2'!T60) -> 0.02864937 | P29: ='AP2'!EB60 / ('AP2'!CG60*'AP2'!T60) -> 0.03196663 | Q29: =('AP2'!EF60+'AP2'!EM60 -'AP2'!EQ60 ) / ('AP2'!CG60*'AP2'!T60) -> 0.26806233 | R29: =0.1*Q29 -> 0.026806233 | S29: =Q29-R29 -> 0.2412561 | T29: =S29-U29 -> 0.23476634 | U29: =('AP2'!EN60+'AP2'!EG60 ) / ('AP2'!CG60*'AP2'!T60) -> 0.0064897641 | Z29: =U29+P29+L29+G29 -> 0.15887749 | AA29: ='A32'!I32*'A30'!N30 -> 0.1162909 | AB29: =(F28+K28+O28+0.3*T28)/(1-AA29) -> 0.24467973 | AC29: =(E28+J28+N28+U28+0.3*T28)/(1-AA29) -> 0.41275684 | AF29: =M29+H29+C29+AA29 -> 1.0040138
A30: CN | B30: 2001 | C30: =D30+E30 -> 0.08327574 | D30: ='AP2'!FZ61 / ('AP2'!CG61*'AP2'!T61) -> 0.071149567 | E30: =F30+G30 -> 0.012126173 | F30: ='AP2'!GA61 / ('AP2'!CG61*'AP2'!T61) -> 0.0092548619 | G30: ='AP2'!DK61 / ('AP2'!CG61*'AP2'!T61) -> 0.0028713108 | H30: =I30+J30 -> 0.49031429 | I30: ='AP2'!FF61 / ('AP2'!CG61*'AP2'!T61) -> 0.25728195 | J30: =K30+L30 -> 0.23303234 | K30: ='AP2'!FG61 / ('AP2'!CG61*'AP2'!T61) -> 0.11784363 | L30: ='AP2'!FB61 / ('AP2'!CG61*'AP2'!T61) -> 0.11518871 | M30: =N30+Q30 -> 0.31737181 | N30: =O30+P30 -> 0.062975661 | O30: ='AP2'!EE61 / ('AP2'!CG61*'AP2'!T61) -> 0.030216914 | P30: ='AP2'!EB61 / ('AP2'!CG61*'AP2'!T61) -> 0.032758747 | Q30: =('AP2'!EF61+'AP2'!EM61 -'AP2'!EQ61 ) / ('AP2'!CG61*'AP2'!T61) -> 0.25439615 | R30: =0.1*Q30 -> 0.025439615 | S30: =Q30-R30 -> 0.22895654 | T30: =S30-U30 -> 0.22293684 | U30: =('AP2'!EN61+'AP2'!EG61 ) / ('AP2'!CG61*'AP2'!T61) -> 0.0060196934 | Z30: =U30+P30+L30+G30 -> 0.15683846 | AA30: ='A32'!I33*'A30'!N31 -> 0.11394844 | AB30: =(F29+K29+O29+0.3*T29)/(1-AA30) -> 0.23815295 | AC30: =(E29+J29+N29+U29+0.3*T29)/(1-AA30) -> 0.41746248 | AF30: =M30+H30+C30+AA30 -> 1.0049103
A31: CN | B31: 2002 | C31: =D31+E31 -> 0.092746821 | D31: ='AP2'!FZ62 / ('AP2'!CG62*'AP2'!T62) -> 0.077481196 | E31: =F31+G31 -> 0.015265626 | F31: ='AP2'!GA62 / ('AP2'!CG62*'AP2'!T62) -> 0.01295893 | G31: ='AP2'!DK62 / ('AP2'!CG62*'AP2'!T62) -> 0.0023066951 | H31: =I31+J31 -> 0.48915891 | I31: ='AP2'!FF62 / ('AP2'!CG62*'AP2'!T62) -> 0.2557299 | J31: =K31+L31 -> 0.23342902 | K31: ='AP2'!FG62 / ('AP2'!CG62*'AP2'!T62) -> 0.12027132 | L31: ='AP2'!FB62 / ('AP2'!CG62*'AP2'!T62) -> 0.1131577 | M31: =N31+Q31 -> 0.29919603 | N31: =O31+P31 -> 0.066701774 | O31: ='AP2'!EE62 / ('AP2'!CG62*'AP2'!T62) -> 0.03369631 | P31: ='AP2'!EB62 / ('AP2'!CG62*'AP2'!T62) -> 0.033005464 | Q31: =('AP2'!EF62+'AP2'!EM62 -'AP2'!EQ62 ) / ('AP2'!CG62*'AP2'!T62) -> 0.23249425 | R31: =0.1*Q31 -> 0.023249425 | S31: =Q31-R31 -> 0.20924483 | T31: =S31-U31 -> 0.20410096 | U31: =('AP2'!EN62+'AP2'!EG62 ) / ('AP2'!CG62*'AP2'!T62) -> 0.0051438643 | Z31: =U31+P31+L31+G31 -> 0.15361372 | AA31: ='A32'!I34*'A30'!N32 -> 0.11789259 | AB31: =(F30+K30+O30+0.3*T30)/(1-AA31) -> 0.25416005 | AC31: =(E30+J30+N30+U30+0.3*T30)/(1-AA31) -> 0.43195978 | AF31: =M31+H31+C31+AA31 -> 0.99899435
A32: CN | B32: 2003 | C32: =D32+E32 -> 0.087992412 | D32: ='AP2'!FZ63 / ('AP2'!CG63*'AP2'!T63) -> 0.076766474 | E32: =F32+G32 -> 0.011225938 | F32: ='AP2'!GA63 / ('AP2'!CG63*'AP2'!T63) -> 0.009134247 | G32: ='AP2'!DK63 / ('AP2'!CG63*'AP2'!T63) -> 0.0020916913 | H32: =I32+J32 -> 0.4793593 | I32: ='AP2'!FF63 / ('AP2'!CG63*'AP2'!T63) -> 0.24868399 | J32: =K32+L32 -> 0.23067531 | K32: ='AP2'!FG63 / ('AP2'!CG63*'AP2'!T63) -> 0.12173373 | L32: ='AP2'!FB63 / ('AP2'!CG63*'AP2'!T63) -> 0.10894158 | M32: =N32+Q32 -> 0.30383218 | N32: =O32+P32 -> 0.070184606 | O32: ='AP2'!EE63 / ('AP2'!CG63*'AP2'!T63) -> 0.034632229 | P32: ='AP2'!EB63 / ('AP2'!CG63*'AP2'!T63) -> 0.035552377 | Q32: =('AP2'!EF63+'AP2'!EM63 -'AP2'!EQ63 ) / ('AP2'!CG63*'AP2'!T63) -> 0.23364757 | R32: =0.1*Q32 -> 0.023364757 | S32: =Q32-R32 -> 0.21028281 | T32: =S32-U32 -> 0.20506308 | U32: =('AP2'!EN63+'AP2'!EG63 ) / ('AP2'!CG63*'AP2'!T63) -> 0.0052197299 | Z32: =U32+P32+L32+G32 -> 0.15180538 | AA32: ='A32'!I35*'A30'!N33 -> 0.12394242 | AB32: =(F31+K31+O31+0.3*T31)/(1-AA32) -> 0.2604359 | AC32: =(E31+J31+N31+U31+0.3*T31)/(1-AA32) -> 0.43578251 | AF32: =M32+H32+C32+AA32 -> 0.9951263
A33: CN | B33: 2004 | C33: =D33+E33 -> 0.086327871 | D33: ='AP2'!FZ64 / ('AP2'!CG64*'AP2'!T64) -> 0.076013092 | E33: =F33+G33 -> 0.010314779 | F33: ='AP2'!GA64 / ('AP2'!CG64*'AP2'!T64) -> 0.0085046951 | G33: ='AP2'!DK64 / ('AP2'!CG64*'AP2'!T64) -> 0.0018100841 | H33: =I33+J33 -> 0.48802878 | I33: ='AP2'!FF64 / ('AP2'!CG64*'AP2'!T64) -> 0.2309603 | J33: =K33+L33 -> 0.25706848 | K33: ='AP2'!FG64 / ('AP2'!CG64*'AP2'!T64) -> 0.14809318 | L33: ='AP2'!FB64 / ('AP2'!CG64*'AP2'!T64) -> 0.1089753 | M33: =N33+Q33 -> 0.29653446 | N33: =O33+P33 -> 0.072339834 | O33: ='AP2'!EE64 / ('AP2'!CG64*'AP2'!T64) -> 0.037717212 | P33: ='AP2'!EB64 / ('AP2'!CG64*'AP2'!T64) -> 0.034622622 | Q33: =('AP2'!EF64+'AP2'!EM64 -'AP2'!EQ64 ) / ('AP2'!CG64*'AP2'!T64) -> 0.22419462 | R33: =0.1*Q33 -> 0.022419462 | S33: =Q33-R33 -> 0.20177516 | T33: =S33-U33 -> 0.1966355 | U33: =('AP2'!EN64+'AP2'!EG64 ) / ('AP2'!CG64*'AP2'!T64) -> 0.0051396578 | Z33: =U33+P33+L33+G33 -> 0.15054766 | AA33: ='A32'!I36*'A30'!N34 -> 0.12348204 | AB33: =(F32+K32+O32+0.3*T32)/(1-AA33) -> 0.25900111 | AC33: =(E32+J32+N32+U32+0.3*T32)/(1-AA33) -> 0.43219252 | AF33: =M33+H33+C33+AA33 -> 0.99437314
... A43: CN | B43: 2014 | C43: =D43+E43 -> 0.07085742 | D43: ='AP2'!FZ74 / ('AP2'!CG74*'AP2'!T74) -> 0.060640848 | E43: =F43+G43 -> 0.010216573 | F43: ='AP2'!GA74 / ('AP2'!CG74*'AP2'!T74) -> 0.0095482428 | G43: ='AP2'!DK74 / ('AP2'!CG74*'AP2'!T74) -> 0.0006683299 | H43: =I43+J43 -> 0.53941888 | I43: ='AP2'!FF74 / ('AP2'!CG74*'AP2'!T74) -> 0.26123103 | J43: =K43+L43 -> 0.27818785 | K43: ='AP2'!FG74 / ('AP2'!CG74*'AP2'!T74) -> 0.19926466 | L43: ='AP2'!FB74 / ('AP2'!CG74*'AP2'!T74) -> 0.078923186 | M43: =N43+Q43 -> 0.26870384 | N43: =O43+P43 -> 0.084497487 | O43: ='AP2'!EE74 / ('AP2'!CG74*'AP2'!T74) -> 0.041523417 | P43: ='AP2'!EB74 / ('AP2'!CG74*'AP2'!T74) -> 0.04297407 | Q43: =('AP2'!EF74+'AP2'!EM74 -'AP2'!EQ74 ) / ('AP2'!CG74*'AP2'!T74) -> 0.18420635 | R43: =0.1*Q43 -> 0.018420635 | S43: =Q43-R43 -> 0.16578572 | T43: =S43-U43 -> 0.15544898 | U43: =('AP2'!EN74+'AP2'!EG74 ) / ('AP2'!CG74*'AP2'!T74) -> 0.010336737 | Z43: =U43+P43+L43+G43 -> 0.13290232 | AA43: ='A32'!I46*'A30'!N44 -> 0.11683091 | AB43: =(F42+K42+O42+0.3*T42)/(1-AA43) -> 0.3341245 | AC43: =(E42+J42+N42+U42+0.3*T42)/(1-AA43) -> 0.48490435 | AF43: =M43+H43+C43+AA43 -> 0.99581105
A44: CN | B44: 2015
A45: CN | B45: 2016

Sheet AP2
A1: Back to index
A2: AP2: National accounts (flow) and other macro series
A3: Notes: Numbers in GREEN color are estimations based on assumpitons
A4: Title | B4: Population | S4: Price Index | W4: Exchange Rates | AB4: Financial and Monentary Market | AW4: Income | CS4: Depreciation | DU4: Capital share | HA4: Saving | IW4: Tax | KC4: Gerenal Government | LL4: Central Government | MS4: Local Government
A5: Sub-title | B5: National Population Statistics | K5: Population by Provinces | AC5: Stocks and Funds | AJ5: Bonds | AT5: Currency | AX5: National Income | BJ5: Producing Approach GDP | BZ5: Income Approach GDP | CF5: Expenditure GDP | CT5: Natioanal KDt | DD5: Housing | DE5: Private | DK5: Government | DN5: Corporation | DQ5: Domestic | DU5: wages paid in selfelmployment | DW5: Total Housing | DY5: Household: Housing | EF5: Household: Agriculture | EM5: Household: Individual Business | ES5: Household: Income of Property | EX5: Memo | EZ5: Corporation: Operation Surplus+House Rent | FL5: Corporation: Income of Property | FT5: Memo | FV5: Government: Operation Surplus+House Rent | GG5: Government: Income of Property | GL5: Memo | GN5: Foreign Sector: Capital Income | GP5: Foreign Sector: Income of Property | GT5: Domestic Economy | HB5: National Saving and Investment on Housing | HG5: Total Economy | HI5: Domestic economy | HO5: Household Saving | HU5: Government Saving | IA5: Corporation Saving | IL5: Foreign Saving | IX5: Central Government Tax | JI5: General Government Tax | JO5: General Government Tax | KA5: General Government Tax | KC5: Government Budget | KM5: Revenue of Government Managed Fund | KX5: State Owned Capital Management | LI5: Social Secuity Funds | LL5: Central Government Budget | LV5: Revenue of Central Government Managed Fund | MG5: Central Government State Owned Capital Management | MS5: Government Budget | NC5: Revenue of Government Managed Fund | NN5: State Owned Capital Management
A6: Data Source | B6: NBS | C6: NBS | D6: NBS | E6: NBS | F6: NBS | G6: Chinese Census and Population sampling survey | H6: Chinese Census and Population sampling survey | K6: China Population and Employment Statistics Yearbook | L6: China Population and Employment Statistics Yearbook | M6: China Population and Employment Statistics Yearbook | N6: China Population and Employment Statistics Yearbook | O6: China Population and Employment Statistics Yearbook | P6: China Population and Employment Statistics Yearbook | X6: NBS/CSY1997 | Y6: WB indicator | AC6: NBS | AD6: NBS | AE6: NBS | AF6: NBS | AJ6: Almanac of China's Finance and Banking 2015 | AK6: Almanac of China's Finance and Banking 2015 | AL6: Almanac of China's Finance and Banking 2015 | AM6: Almanac of China's Finance and Banking 2015 | AN6: Almanac of China's Finance and Banking 2015 | AO6: Almanac of China's Finance and Banking 2015 | AP6: Almanac of China's Finance and Banking 2015 | AQ6: Almanac of China's Finance and Banking 2015 | AR6: Almanac of China's Finance and Banking 2015 | AT6: NBS | AX6: CYS2014/2016 | AY6: CYS2014/2016 | AZ6: rent corr. | BA6: rent corr. | BC6: NBS IO Table | BD6: GDP of China 1952-2004 (NBS2004) | BE6: GDP of China 1952-2004 (NBS2004) | BF6: rent corr. | BG6: rent corr. | BJ6: NBS2004/CYS2014/CYS2016 | BK6: rent corr. | BL6: NBS2004/CYS2014/CYS2016 | BM6: NBS2004/CYS2014/CYS2016 | BN6: NBS2004/CYS2014/CYS2016 | BO6: NBS2004/CYS2014/CYS2016 | BP6: NBS2004/CYS2014/CYS2016 | BQ6: rent corr. | BR6: NBS2004/CYS2014/CYS2016 | BS6: NBS2004/CYS2014/CYS2016 | BT6: NBS2004/CYS2014/CYS2016 | BU6: NBS2004/CYS2014/CYS2016 | BV6: NBS2004/CYS2014/CYS2016 | BW6: rent corr. | BX6: NBS2004/CYS2014/CYS2016 | BY6: ` | BZ6: NBS2004/CYS2006-2013 | CA6: NBS2004/CYS2006-2013 | CB6: NBS2004/CYS2006-2013 | CC6: NBS2004/CYS2006-2013 | CD6: NBS2004/CYS2006-2013 | CF6: CYS2014 | CG6: rent corr. | CI6: CYS2014 | CJ6: rent corr. | CK6: CYS2014 | CL6: rent corr. | CM6: CYS2014 | CN6: CYS2014 | CO6: CYS2014 | CP6: CYS2014 | CT6: NBS IO Table | CW6: CSY1994 | CY6: NBS IO Table | CZ6: NBS2004/CYS2006-2013 | DA6: WB WDI | DB6: WB WDI | DW6: corr. rent | DY6: CYS2008/2012 | EA6: corr. Rent | EE6: corr. rent | EM6: FoF | EO6: FoF | EQ6: FoF | ES6: FoF | ET6: FoF | EU6: FoF | EV6: FoF | EW6: FoF | EX6: FoF | EZ6: FoF (corr. Rent) | FA6: corr. rent | FC6: FoF (corr. production tax1992-1999) | FF6: FoF (corr. Rent and production tax1992-1999) | FG6: FoF (corr. Rent and production tax1992-1999) | FL6: FoF | FM6: FoF | FN6: FoF | FO6: FoF | FP6: FoF | FT6: FoF | FV6: FoF (corr. Rent) | FW6: corr. rent | FY6: FoF | FZ6: FoF | GB6: FoF | GC6: FoF | GD6: FoF | GE6: FoF | GF6: FoF | GG6: FoF | GH6: FoF | GI6: FoF | GJ6: FoF | GK6: FoF | GL6: FoF | GN6: FoF | GO6: FoF | GP6: FoF | GQ6: FoF | GR6: FoF | GT6: FoF | GV6: FoF | GW6: FoF | HB6: NBS | HC6: NBS | HD6: NBS | HE6: NBS | HG6: FOF | HI6: FOF | HJ6: corr. Foreign share of corporate saving | HK6: FOF | HL6: FOF (corr. Foreign share of corporate saving) | HM6: FOF | HO6: FoF (corr. Production tax 1992-1999) | HP6: corr. Production tax 1992-1999 | HQ6: FOF | HR6: FoF (corr. Production tax 1992-1999) | HS6: FOF | HU6: FOF | HV6: corr. Production tax 1992-1999 | HW6: FOF | HX6: FoF (corr. Production tax 1992-1999) | HY6: FOF | IA6: FOF | IB6: FOF | IC6: FOF | ID6: FoF (corr. Production tax 1992-1999) | IE6: FOF | IF6: FOF | IG6: FOF | IH6: FOF | II6: FoF (corr. Production tax 1992-1999) | IJ6: FOF | IL6: FoF | IM6: FoF | IN6: FoF | IO6: FoF | IP6: FoF | IQ6: FoF | IR6: FoF | IS6: FoF | IT6: FoF | IX6: ICTDGRD June2016 | IY6: ICTDGRD June2016 | IZ6: ICTDGRD June2016 | JA6: ICTDGRD June2016 | JB6: ICTDGRD June2016 | JC6: ICTDGRD June2016 | JD6: ICTDGRD June2016 | JE6: ICTDGRD June2016 | JF6: ICTDGRD June2016 | JG6: ICTDGRD June2016 | JI6: FoF | JJ6: FoF | JK6: FoF | JL6: FoF | JM6: FoF | JO6: NBS | JP6: NBS | JQ6: NBS | JR6: NBS | JS6: NBS | JT6: NBS | JU6: NBS | JV6: NBS | JW6: NBS | JX6: NBS | JY6: NBS | KA6: Financial Yearbook of China 2015 | KC6: Financial Yearbook and MOF | KD6: Financial Yearbook and MOF | KE6: FoF | KF6: Financial Yearbook and MOF | KG6: Financial Yearbook and MOF | KH6: Financial Yearbook and MOF | KI6: Financial Yearbook and MOF | KJ6: Financial Yearbook and MOF | KK6: Financial Yearbook and MOF | KL6: Financial Yearbook and MOF | KM6: Financial Yearbook and MOF | KN6: Financial Yearbook and MOF | KO6: Financial Yearbook and MOF | KP6: Financial Yearbook and MOF | KQ6: Financial Yearbook and MOF | KR6: Financial Yearbook and MOF | KS6: Financial Yearbook and MOF | KT6: Financial Yearbook and MOF | KU6: Financial Yearbook and MOF | KV6: Financial Yearbook and MOF | KW6: Financial Yearbook and MOF | KX6: Financial Yearbook and MOF | KY6: Financial Yearbook and MOF | KZ6: Financial Yearbook and MOF | LA6: Financial Yearbook and MOF | LB6: Financial Yearbook and MOF | LC6: Financial Yearbook and MOF | LD6: Financial Yearbook and MOF | LE6: Financial Yearbook and MOF | LF6: Financial Yearbook and MOF | LG6: Financial Yearbook and MOF | LH6: Financial Yearbook and MOF | LI6: Financial Yearbook and MOF | LJ6: Financial Yearbook and MOF | LL6: Financial Yearbook and MOF | LM6: Financial Yearbook and MOF | LN6: Based on FoF | LO6: Financial Yearbook and MOF | LP6: Financial Yearbook and MOF | LQ6: Financial Yearbook and MOF | LR6: Financial Yearbook and MOF | LS6: Financial Yearbook and MOF | LT6: Financial Yearbook and MOF | LU6: Financial Yearbook and MOF | LV6: Financial Yearbook and MOF | LW6: Financial Yearbook and MOF | LX6: Financial Yearbook and MOF | LY6: Financial Yearbook and MOF | LZ6: Financial Yearbook and MOF | MA6: Financial Yearbook and MOF | MB6: Financial Yearbook and MOF | MC6: Financial Yearbook and MOF | MD6: Financial Yearbook and MOF | ME6: Financial Yearbook and MOF | MF6: Financial Yearbook and MOF | MG6: Financial Yearbook and MOF | MH6: Financial Yearbook and MOF | MI6: Financial Yearbook and MOF | MJ6: Financial Yearbook and MOF | MK6: Financial Yearbook and MOF | ML6: Financial Yearbook and MOF | MM6: Financial Yearbook and MOF | MN6: Financial Yearbook and MOF | MO6: Financial Yearbook and MOF | MP6: Financial Yearbook and MOF | MQ6: Financial Yearbook and MOF | MS6: Financial Yearbook and MOF | MT6: Financial Yearbook and MOF | MU6: Based on FoF | MV6: Financial Yearbook and MOF | MW6: Financial Yearbook and MOF | MX6: Financial Yearbook and MOF | MY6: Financial Yearbook and MOF | MZ6: Financial Yearbook and MOF | NA6: Financial Yearbook and MOF | NB6: Financial Yearbook and MOF | NC6: Financial Yearbook and MOF | ND6: Financial Yearbook and MOF | NE6: Financial Yearbook and MOF | NF6: Financial Yearbook and MOF | NG6: Financial Yearbook and MOF | NH6: Financial Yearbook and MOF | NI6: Financial Yearbook and MOF | NJ6: Financial Yearbook and MOF | NK6: Financial Yearbook and MOF | NL6: Financial Yearbook and MOF | NM6: Financial Yearbook and MOF | NN6: Financial Yearbook and MOF | NO6: Financial Yearbook and MOF | NP6: Financial Yearbook and MOF | NQ6: Financial Yearbook and MOF | NR6: Financial Yearbook and MOF | NS6: Financial Yearbook and MOF | NT6: Financial Yearbook and MOF | NU6: Financial Yearbook and MOF | NV6: Financial Yearbook and MOF | NW6: Financial Yearbook and MOF | NX6: Financial Yearbook and MOF | NZ6: Naughton 2017 | OA6: Naughton 2017 | OB6: Naughton 2017 | OC6: Naughton 2017
A7: Series | B7: Total population | C7: Urban Population | D7: Rural Population | E7: Employed Population | F7: Persons per household in rural China | G7: % 0-19 | H7: * 20+ | I7: Population of adults | K7: Population in Guangdong | L7: Population in Beijing | M7: Population in Hubei | N7: Population in Zhejiang | O7: Population in Shanxi(山西） | P7: Population in Heilongjiang | T7: Young GDP deflator, (2015=100%) | X7: NBS Exchange Rage,Period average | Y7: PPP conversion factor, GDP (LCU per international $)PPP | AC7: Total Market Capitalization | AD7: Negotiable Market Capitalization | AE7: Capital of Securities Investment Funds | AF7: Raised Capital by New Issues | AG7: New Issues | AH7: Capital gain of total stock market | AJ7: Issued national bonds | AK7: Payback national bonds | AL7: Outstanding national bonds | AM7: Issued financial bonds | AN7: Payback financial bonds | AO7: Outstanding financial bonds | AP7: Issued corporate bonds | AQ7: Payback corporate bonds | AR7: Outstanding corporatel bonds | AT7: M0 Supply | AX7: GNI | AY7: GDP (Producing approach) | AZ7: GNI | BA7: GDP (Producing approach) | BB7: GNI minus GDP | BC7: Total Value Added | BD7: GNI | BE7: GDP(Producing approach) | BF7: NI | BG7: NI | BH7: NI / Adult | BJ7: Producing approach GDP | BK7: Producing approach GDP | BL7: PrimaryIndustry | BM7: Secondary Industry | BN7: Industry | BO7: Construction | BP7: Tertiary industry | BQ7: Tertiary industry | BR7: Transport,storage, and post | BS7: Wholesale and retail trade | BT7: Hotels and catering service | BU7: Financial Intermediation | BV7: Real Estate | BW7: Real Estate | BX7: Others | BZ7: Value-added | CA7: Compensation of Employees | CB7: Depreciation of Fixed Assets | CC7: Net Taxes on Production | CD7: Operating Surplus | CF7: GDP | CG7: GDP | CH7: Statistical discrepancy between GDI and GDP | CI7: Household consumption | CJ7: Household consumption | CK7: Government consumption | CL7: Government consumption | CM7: I (total capital formation) | CN7: Total fixed capital formation | CO7: Inventory | CP7: Net export | CT7: Capital depreciation of GDP | CU7: Capital depreciation rate of GDP | CV7: Implied capital depreciation rate of GDP | CW7: Depreciation rate of fixed capital of SOE | CX7: Estimated Depreciation (KDt) | CY7: Total Estimated Depreciation KDt | CZ7: Depreciation of Fixed Assets | DA7: Depreciation (KDt) | DB7: Depreciation (KDt) | DD7: KDt on Housing | DE7: KDt on private owned housing | DF7: incl: rural housing | DG7: incl: urban housing | DH7: KDt on Household ownned domestic capital | DI7: Incl: productive capital cfc in rural China | DJ7: incl: individual business capital cfc | DK7: KDt on government non-corporation asset | DL7: incl: gov owned housing | DM7: incl: other domestic capital | DN7: KDt of Corporations Sector | DO7: incl: corp owned housing | DP7: incl: other domestic capital | DQ7: KDt | DW7: Total Rent of Housing | DX7: Housing output | DY7: Value added on housing (cost approach=Consumption on housing) | DZ7: Intermediate goods and services consumed | EA7: Value added on housing (cost approach=Consumption on housing) | EB7: KDt on Housing | EC7: Compensation of Employees | ED7: Tax on production | EE7: Net profit | EF7: Value added on agriculture | EG7: KDt on productive capital in rural China | EH7: Tax on production | EI7: Compensation of Employees | EJ7: Net profit | EK7: corr. Compensation of employee | EL7: corr. Net profit | EM7: Value added of individual business | EN7: KDt on individual business capital | EO7: Compensation of Employees | EP7: corr. Compensation of Compensation of Employees | EQ7: Tax on production | ER7: Net profit | ES7: Total net income of property | ET7: incl. net interest | EU7: incl. net distributed Income of Corporations | EV7: incl. net rent on Land | EW7: incl. net other Income from Properties | EX7: Land selling revenue | EZ7: Value added in corporation sector | FA7: rent of corp housing | FB7: KDt in corporation sector | FC7: Tax on production | FD7: adjust for tax on production (diff between NBS and FoF) | FE7: labor share (before correct tax on production) | FF7: Compensation of Employees | FG7: Net Profit | FH7: incl. net income from property use | FI7: incl. corp income tax use | FJ7: incl. net other transfer use | FK7: incl. retainer earnings | FL7: Total net income of property | FM7: incl. net interest | FN7: incl. net distributed Income of Corporations | FO7: incl. net rent on Land | FP7: incl. net other Income from Properties | FQ7: incl:Private capital gain share | FR7: incl:Public capital gain share | FS7: incl:Foreign capital gain share | FT7: Land selling revenue | FV7: Value added in government secotr | FW7: rent of pub housing | FX7: KDt in corporation sector | FY7: Tax on production | FZ7: Compensation of Employees | GA7: Net Profit | GB7: Other net property income | GC7: incl: net interest | GD7: incl: rent on land | GE7: incl: others | GF7: incl: profit from government owned corporation | GG7: Total net income of property | GH7: incl. net interest | GI7: incl. net distributed Income of Corporations | GJ7: incl. net rent on Land | GK7: incl. net other Income from Properties | GL7: Land selling revenue | GN7: Net income from properties | GO7: Net Compensation of Employees | GP7: Total net income of property | GQ7: incl. net interest | GR7: incl. net distributed Income of Corporations | GT7: Value added in government secotr | GU7: KDt in corporation sector | GV7: Tax on production | GW7: Compensation of Employees | GX7: Net Profit | HB7: Savings Deposit of Urban and Rural Households | HC7: Total investment on residential housing | HD7: Total investment on residential housing | HE7: Net investment on residential housing | HG7: Gross savings of total economy | HI7: Gross domestic savings (after net capital transfers paid) | HJ7: Net domestic savings (after net capital transfers paid) | HK7: incl:net Non-financial assets saving | HL7: incl:net financial assets saving | HM7: incl:net capital transfer | HO7: Gross Personel Savings | HP7: Net Personel Saving | HQ7: incl:net Non-financial assets saving | HR7: incl:net financial assets saving | HS7: incl:net capital transfer | HU7: Gross Government Savings | HV7: Net Government Savings | HW7: incl:net Non-financial assets saving | HX7: incl:net financial assets saving | HY7: incl:net capital transfer | IA7: Non-financial corporate Savings | IB7: Financial corporate Savings | IC7: Corporate retained earnings | ID7: Net corporate retained earnings | IE7: incl:Private saving share | IF7: incl:Public saving share | IG7: incl:foreign saving share | IH7: incl:net Non-financial assets saving | II7: incl:net financial assets saving | IJ7: incl:net capital transfer | IL7: Total Saving Rest of the World | IM7: Foreign share of corporate retain earnings | IN7: Saving Rest of the World (1+2+3+4)=-(5+6) | IO7: incl: Net Export | IP7: incl: Compensation of Employees | IQ7: incl: Income from Properties | IR7: incl: Current Transfer | IS7: incl: Capital Transfer | IT7: incl: Net Financial Investment | IX7: Total Revenue_GG (excluding grants and social contribution) | IY7: 1. Non-tax Revenue_GG | IZ7: 2. Total Tax_GG | JA7: 2.1 Direct Tax_GG | JB7: 2.1.1 Income Tax_GG | JC7: 2.1.1.1 Individual Income Tax_GG | JD7: 2.1.1.2 Corporate Income Tax_GG | JE7: 2.2 Indirect Tax_GG | JF7: 2.2.1 Tax on Good and Servance_GG | JG7: 2.2.2 Other Tax_GG | JI7: Income Tax_GG | JJ7: Individual Income Tax_GG | JK7: Corporate Income Tax_GG | JL7: Indirect Tax_GG | JM7: Total tax_GG | JO7: Total Budget Revenue | JP7: Non-Tax Revenue | JQ7: Tax Revenue | JR7: Indirect Tax | JS7: Value Added Tax | JT7: Business Tax | JU7: Excises/Consumer Tax | JV7: Trade Tax | JW7: Direct Tax | JX7: Individual Income Tax | JY7: Corporate Income Tax | KA7: Total Tax Revenue | KC7: Total | KD7: Tax revenue | KE7: Tax revenue | KF7: Non-tax revenue | KG7: Special Revenue | KH7: Administrative and Institutional Charges | KI7: Fines and Penalties | KJ7: Profits of State-owned Enterprises | KK7: Revenues from the compensated use of state-owned resources (or assets） | KL7: Other non-tax revenue | KM7: Total | KN7: Railway Construction Fund | KO7: Local education Surcharges | KP7: Compensable Payment for Newly Used Land | KQ7: Sale Receipt of State-owned Land-use Rights | KR7: State-owned Land Return Fund | KS7: Financial Revenue From Central Special Debt Management | KT7: Lottery Proceeds | KU7: Urban Infrastructure Supporting Fees | KV7: Tolls | KW7: Other Revenue | KX7: Total | KY7: Profit Revenue | KZ7: Tabacco | LA7: Petroleum and Petrochemical | LB7: Telecommunication | LC7: Eclectricity Power | LD7: Coal | LE7: other | LF7: Interest and Dividend | LG7: Property Right Transfer (less holding of state-owned stocks) | LH7: Other | LI7: Revenue of Social Secuity Funds | LJ7: Off-budget revenue | LL7: Total | LM7: Tax revenue | LN7: Tax revenue | LO7: Non-tax revenue | LP7: Special Revenue | LQ7: Administrative and Institutional Charges | LR7: Fines and Penalties | LS7: Profits of State-owned Enterprises | LT7: Revenues from the compensated use of state-owned resources (or assets | LU7: Other non-tax revenue | LV7: Total | LW7: Railway Construction Fund | LX7: Local education Surcharges | LY7: Compensable Payment for Newly Used Land | LZ7: Sale Receipt of State-owned Land-use Rights | MA7: State-owned Land Return Fund | MB7: Financial Revenue From Central Special Debt Management | MC7: Lottery Proceeds | MD7: Urban Infrastructure Supporting Fees | ME7: Tolls | MF7: Other Revenue | MG7: Total | MH7: Profit Revenue | MI7: Tabacco | MJ7: Petroleum and Petrochemical | MK7: Telecommunication | ML7: Eclectricity Power | MM7: Coal | MN7: other | MO7: Interest and Dividend | MP7: Property Right Transfer (less holding of state-owned stocks) | MQ7: Other | MS7: Total | MT7: Tax revenue | MU7: Tax revenue | MV7: Non-tax revenue | MW7: Special Revenue | MX7: Administrative and Institutional Charges | MY7: Fines and Penalties | MZ7: Profits of State-owned Enterprises | NA7: Revenues from the compensated use of state-owned resources (or assets | NB7: Other non-tax revenue | NC7: Total | ND7: Railway Construction Fund | NE7: Local education Surcharges | NF7: Compensable Payment for Newly Used Land | NG7: Sale Receipt of State-owned Land-use Rights | NH7: State-owned Land Return Fund | NI7: Financial Revenue From Central Special Debt Management | NJ7: Lottery Proceeds | NK7: Urban Infrastructure Supporting Fees | NL7: Tolls | NM7: Other Revenue | NN7: Total | NO7: Profit Revenue | NP7: Tabacco | NQ7: Petroleum and Petrochemical | NR7: Telecommunication | NS7: Eclectricity Power | NT7: Coal | NU7: other | NV7: Interest and Dividend | NW7: Property Right Transfer (less holding of state-owned stocks) | NX7: Other | NZ7: Government Budget (fiscal revenue. Adj. ) | OA7: Revenue of Social Insurance Funds | OB7: Land Revenue | OC7: SOE Profit
A8: Notes | F8: Based on rural household survey. Assuming 2013 to 2015 data is 3.9 equal 2012 | Y8: For a few countries where the official exchange rate does not reflect the rate effectively applied to actual foreign exchange transactions, an alternative conversion factor is used. (WDI notes, online) | AJ8: including centrol gov bonds + local gov bonds | AL8: For 2015, we use average growth rate in the last 5 years to estimate. | AO8: For 2015, we use average growth rate in the last 5 years to estimate. | AR8: For 2015, we use average growth rate in the last 5 years to estimate. | AX8: Data is concistent with NBS FOF data. Data in 2013 and 2014 is from NBS FOF. Data in 2015 is from CYS2016 | AY8: Data is consistent with FOF. Data in 2013 and 2014 is from NBS FOF value added, which is equal to producing approach GDP. Data in 2013 and 2014 is from NBS FOF. Data in 2015 is from CYS2016. | AZ8: Data is concistent with NBS FOF data. Data in 2013 and 2014 is from NBS FOF. Data in 2015 is from CYS2016 | BA8: Data is consistent with FOF. Data in 2013 and 2014 is from NBS FOF value added, which is equal to producing approach GDP. Data in 2013 and 2014 is from NBS FOF. Data in 2015 is from CYS2016. | BC8: TVA is measured at factor cost prices. the summation of value added Input-Output Tables of China is slightly different from GDP, which mainly results from the factors such as different disposal methods on customs duty of import, allocation of insurance service, special treatment on sector of scraps and wases, and so on. | BD8: Historical data was modified in 2004 by NBS. | BF8: GNI-KD | BG8: GNI-KD | BJ8: 1952-2002 (NBS2004) 2003-2012 (CYS2014) 2013 is from CYS2015 | BK8: 1952-2002 (NBS2004) 2003-2012 (CYS2014) 2013 is from CYS2015 | BL8: 1952-2002 (NBS2004) 2003-2012 (CYS2014) 2013 is from CYS2015 | BM8: 1952-2002 (NBS2004) 2003-2012 (CYS2014) 2013 is from CYS2015 | BP8: 1952-2002 (NBS2004) 2003-2012 (CYS2014) 2013 is from CYS2018 | BQ8: 1952-2002 (NBS2004) 2003-2012 (CYS2014) 2013 is from CYS2018 | BZ8: sum of the income approach provincial GDP | CH8: Expenditure GDP-Producing approach GDP | CI8: Data in 2013 is from FoF 2013, which is equal to FoF household consumption | CJ8: Data in 2013 is from FoF 2013, which is equal to FoF household consumption | CK8: Data in 2013 is from FoF 2013, which is equal to FoF government consumption | CL8: Data in 2013 is from FoF 2013, which is equal to FoF government consumption | CM8: Data in 2013 is from cys 2015, which is equal to data in FoF 2013, which is equal to fof capital formation+ Acquisitions Less Disposals of Other Non-financial Assets | CP8: Data in 2013 is from FoF 2013. In 1999, fof net export=2375.7, which is equal to FoF net export | CT8: Data is measured at factor cost prices | CU8: equal to capital depreciation/TVA | CV8: assuming the percentage change linearly between the gap.before 1987, we asuming the depreciation is 11% | CX8: kdt%*GDP | CZ8: From income approach of GDP by province | DA8: compution of fixed capital | DB8: wb appreciation is too samll | DD8: Depreciation rate is 2% of house current value in urban China, 3% of house current value in rural China (equalt to CV+DC+DF) | DH8: Assuming depreciation ratio is 5% of market value, before 1992 assuming the growth rate is 10% for domestice capital | DK8: Including government institutions and administrations. In china these assets do not calculate cfc. | DN8: Non FA depreciation+corporate owned housing depreciation | DW8: based on NBS GDP guide book, houseing profit is equal to 0. here we make an adjustment net housing profit is equal to 0.02 housing stock | DY8: Consumption on housing=Selfowned house depreciation (owner occupied, urban DR is 2%, rural DR is 3%,maintance and manage fee, utilities) | DZ8: maintance and manage fee, utilities, before 2004 assuming it is equal to 50% of CFC,after 2011 it is equal to 20% of CFC. | EA8: value added on housing =housing output-intermediate goods and service cost | EB8: 2% in urban China, 3% in rural China | EF8: Based on NBS GDP guide book | EG8: assuming cfc/productive capital=0.05 | EJ8: In NBS GDP guide book, net profit of household agriculture is 0 | EL8: 30% of vat-kd-tax | EN8: assuming cfc/productive capital=0.05 | EP8: in nbs gdp codebook, the wage and profit of individual business owners are included in the profit section. | ER8: assuming net profit is equal to 5%(vat-kdt-tax) | ET8: interest rate from deposit and bonds. (deposit interest-loan interest) | EU8: dividens from listed companies only | EV8: no info | EW8: insurance income-insurance payment | FC8: Before 1999 (incl 1999), we use data from NBS | FE8: compensation/(compensation+net profit) | FF8: split tax correction between compensation and net profit based on the before correction share | FM8: interest rate from deposit and bonds. (deposit interest-loan interest) | FN8: dividens from listed companies only | FO8: no info | FP8: insurance income-insurance payment | FX8: kd in government sector is 0 | GH8: interest rate from deposit and bonds. (deposit interest-loan interest) | GI8: deviden of non-tradable share of the A stock market | GJ8: no info | GK8: no info | GQ8: interest rate from deposit and bonds. (deposit interest-loan interest) | GR8: deviden of non-tradable share of the A stock market | GT8: domestic economy value added | GU8: kd in government sector is 0 | GV8: tax on production in deomestic capital | GW8: compensation in deomestic capital | HB8: from 2011 to 2014, data is from "Credit balance table of financial institutions, source", before 2011, data is from "urban and rural household savings". For 2015,We use the average growth rate of last 5 years to estimate. | HG8: gross capital transfers | HI8: gross capital transfers | HJ8: gross capital transfers (including foreign share of corporate saving) | HK8: including Acquisitions Less Disposals of Other Non-financial Assets=0 | HO8: gross capital transfers | HQ8: NFA saving-KDt of household, including Acquisitions Less Disposals of Other Non-financial Assets | HU8: gross capital transfers | HV8: gross capital transfers | HW8: including Acquisitions Less Disposals of Other Non-financial Assets | IA8: gross capital transfers | IB8: gross capital transfers | IC8: Non Financial+Financial | ID8: CRE-KD of corporation sector | IH8: including Acquisitions Less Disposals of Other Non-financial Assets | IL8: gross capital transfers | IM8: gross capital transfers | IN8: gross capital transfers | IX8: Central + Local government | JO8: very close to barry naughton's gov bud rev | JP8: Including, Special Program Receipts, Charge of Administrative and Institutional Units, Penalty Receipts, and Other Non-tax Receipts | JQ8: Data is consistent with CompendiumOfStatistics 1949-2008 (table 0116). Data after 1997 is consistent with finance year book | JX8: data before 1998, including 1998 is from Tax Yearbook of China | KA8: data before 1997 is not consistent with NBS data | KD8: consistent with NBS data | KF8: consistent with NBS data | KJ8: inclued in other non-tax revenue before 2014 | KK8: inclued in other non-tax revenue before 2014 | LJ8: in 1992, we exclude revenue from SOEs ect. After 1993, revenue from SOEs are excluded from off budget revenue.
