Workbook
Name \0: #REF!
Name \66: '[1](2)'!#REF!
Name \L: #REF!
Name _L: #REF!
Name building: #REF!
Name building: #REF!
Name CCODE: #REF!
Name CHANEL2: #REF!
Name CNAME2: #REF!
Name CNAME3: #REF!
Name CNAME4: #REF!
Name Consolidated: #REF!
Name COUNTER: #REF!
Name D: #REF!
Name GIVEM1: #REF!
Name LOOP: #REF!
Name menuitem: #REF!
Name STAT: #REF!
Name STOP: #REF!
Name yy: #REF!
Name yy: #REF!
Name الزراعة: #REF!
Name الغ: #REF!
Name ي: #REF!
Name ئ2094: #REF!
Name ئ2094: #REF!
Name يبابل: #REF!

Sheet SA
C4: Goverment Sector | D4: Components Goverment Sector | H4: Corporate Sector | I4: Components Corporate Sector | M4: Household Sector | N4: Components Household Sector | V4: Total Economy | AB4: Capital Shares
N5: Housing | Q5: Self-employment | V5: compen-sation of employees | W5: Net Mixed- income and OS | X5: Gross Operating Surplus | Y5: Mixed Income | AG5: Checks
A6: Notes | O6: Housing included in mixed income most likely. Assume 1/3 of mixed income is housing
A7: iso | B7: year | C7: gvago | D7: ceugo | E7: gsrgo | F7: nsrgo | G7: cfcgo | H7: gvaco | I7: ceuco | J7: gsrco | K7: nsrco | L7: cfcco | M7: gvahn | N7: gsrhn | O7: nsrhn | P7: ccshn | Q7: gvmhn | R7: ceuhn | S7: gmxhn | T7: nmxhn | U7: ccmhn | V7: comhn | Y7: gmxhn | Z7: confc | AA7: ptxgo | AB7: cshare | AC7: cshare_gross | AD7: cshare_corp | AE7: chare_corp_gross | AF7: check_sector | AG7: check_total
A8: SA | B8: 2000 | AF8: =N8+Q8+H8+C8+AA8 -> 0 | AG8: =V8+X8+AA8+Y8 -> 0
A9: SA | B9: 2001
A10: SA | B10: 2002
A11: SA | B11: 2003
A12: SA | B12: 2004
A13: SA | B13: 2005
A14: SA | B14: 2006
A15: SA | B15: 2007
A16: SA | B16: 2008
A17: SA | B17: 2009
A18: SA | B18: 2010
A19: SA | B19: 2011
A20: SA | B20: 2012
A21: SA | B21: 2013 | C21: =D21+E21 -> 0.131457 | D21: ='SA_raw Sheet2'!G8 -> 0.11434405 | E21: =G21 -> 0.017112946 | F21: 0 | G21: ='SA_raw Sheet2'!E8 -> 0.017112946 | H21: =I21+J21 -> 0.71973555 | I21: ='SA_raw Sheet2'!K8 -> 0.067358899 | J21: =K21+L21 -> 0.65237665 | K21: ='SA_raw Sheet2'!I8 -> 0.58808926 | L21: ='SA_raw Sheet2'!H8 -> 0.06428739 | M21: =N21+Q21 -> 0.13820182 | N21: =O21+P21 -> 0.039714964 | O21: ='SA_raw Sheet2'!N8*(1/3) -> 0.039656391 | P21: ='SA_raw Sheet2'!R8 -> 5.8572956e-05 | Q21: =R21+S21 -> 0.098486853 | R21: ='SA_raw Sheet2'!L8 -> 0.014821815 | S21: =T21+U21 -> 0.083665038 | T21: ='SA_raw Sheet2'!N8*(2/3) -> 0.079312782 | U21: ='SA_raw Sheet2'!P8 -> 0.0043522563 | V21: ='SA_raw Sheet2'!D8 -> 0.19654012 | W21: =K21+O21+T21 -> 0.70705843 | Z21: ='SA_raw Sheet2'!C8 -> 0.085781165 | AA21: ='SA_raw Sheet2'!S8 -> 0.00756234 | AD21: =J21/H21 -> 0.9064116 | AF21: =C21+H21+M21+AA21 -> 0.99695671
A22: SA | B22: 2014 | C22: =D22+E22 -> 0.13804395 | D22: ='SA_raw Sheet2'!G9 -> 0.11875695 | E22: =G22 -> 0.019287004 | F22: 0 | G22: ='SA_raw Sheet2'!E9 -> 0.019287004 | H22: =I22+J22 -> 0.69835745 | I22: ='SA_raw Sheet2'!K9 -> 0.066988352 | J22: =K22+L22 -> 0.63136909 | K22: ='SA_raw Sheet2'!I9 -> 0.56402817 | L22: ='SA_raw Sheet2'!H9 -> 0.067340922 | M22: =N22+Q22 -> 0.14854702 | N22: =O22+P22 -> 0.042959512 | O22: ='SA_raw Sheet2'!N9*(1/3) -> 0.042907332 | P22: ='SA_raw Sheet2'!R9 -> 5.21804e-05 | Q22: =R22+S22 -> 0.10558751 | R22: ='SA_raw Sheet2'!L9 -> 0.015266293 | S22: =T22+U22 -> 0.090321217 | T22: ='SA_raw Sheet2'!N9*(2/3) -> 0.085814664 | U22: ='SA_raw Sheet2'!P9 -> 0.0045065532 | V22: ='SA_raw Sheet2'!D9 -> 0.20462685 | W22: =K22+O22+T22 -> 0.69275017 | Z22: ='SA_raw Sheet2'!C9 -> 0.090927521 | AA22: ='SA_raw Sheet2'!S9 -> 0.0082924528 | AD22: =J22/H22 -> 0.90407727 | AF22: =C22+H22+M22+AA22 -> 0.99324088
A23: SA | B23: 2015 | C23: =D23+E23 -> 0.19362734 | D23: ='SA_raw Sheet2'!G10 -> 0.16861462 | E23: =G23 -> 0.025012716 | F23: 0 | G23: ='SA_raw Sheet2'!E10 -> 0.025012716 | H23: =I23+J23 -> 0.61109422 | I23: ='SA_raw Sheet2'!K10 -> 0.088852225 | J23: =K23+L23 -> 0.52224199 | K23: ='SA_raw Sheet2'!I10 -> 0.42754957 | L23: ='SA_raw Sheet2'!H10 -> 0.094692425 | M23: =N23+Q23 -> 0.18085381 | N23: =O23+P23 -> 0.051397344 | O23: ='SA_raw Sheet2'!N10*(1/3) -> 0.05131379 | P23: ='SA_raw Sheet2'!R10 -> 8.3553698e-05 | Q23: =R23+S23 -> 0.12945647 | R23: ='SA_raw Sheet2'!L10 -> 0.019971372 | S23: =T23+U23 -> 0.1094851 | T23: ='SA_raw Sheet2'!N10*(2/3) -> 0.10262758 | U23: ='SA_raw Sheet2'!P10 -> 0.0068575169 | V23: ='SA_raw Sheet2'!D10 -> 0.27808586 | W23: =K23+O23+T23 -> 0.58149094 | Z23: ='SA_raw Sheet2'!C10 -> 0.12664662 | AA23: ='SA_raw Sheet2'!S10 -> 0.010595016 | AD23: =J23/H23 -> 0.85460143 | AF23: =C23+H23+M23+AA23 -> 0.99617039
A24: SA | B24: 2016 | C24: =C23+(C$26-C$23)/3 -> 0.18942647 | D24: =D23+(D$26-D$23)/3 -> 0.16485392 | E24: =E23+(E$26-E$23)/3 -> 0.024572548 | F24: =F23+(F$26-F$23)/3 -> 0 | G24: =G23+(G$26-G$23)/3 -> 0.024572548 | H24: =H23+(H$26-H$23)/3 -> 0.62437863 | I24: =I23+(I$26-I$23)/3 -> 0.087001107 | J24: =J23+(J$26-J$23)/3 -> 0.53737753 | ... V24: =V23+(V$26-V$23)/3 -> 0.18539057 | X24: =X23+(X$26-X$23)/3 -> 0 | Y24: =Y23+(Y$26-Y$23)/3 -> 0 | Z24: =Z23+(Z$26-Z$23)/3 -> 0.084431079 | AA24: =AA23+(AA$26-AA$23)/3 -> 0.02330666
A25: SA | B25: 2017 | C25: =C24+(C$26-C$23)/3 -> 0.1852256 | D25: =D24+(D$26-D$23)/3 -> 0.16109322 | E25: =E24+(E$26-E$23)/3 -> 0.024132379 | F25: =F24+(F$26-F$23)/3 -> 0 | G25: =G24+(G$26-G$23)/3 -> 0.024132379 | H25: =H24+(H$26-H$23)/3 -> 0.63766305 | I25: =I24+(I$26-I$23)/3 -> 0.085149989 | J25: =J24+(J$26-J$23)/3 -> 0.55251306 | ... V25: =V24+(V$26-V$23)/3 -> 0.092695287 | X25: =X24+(X$26-X$23)/3 -> 0 | Y25: =Y24+(Y$26-Y$23)/3 -> 0 | Z25: =Z24+(Z$26-Z$23)/3 -> 0.04221554 | AA25: =AA24+(AA$26-AA$23)/3 -> 0.036018304
A26: SA | B26: 2018 | C26: =D26+E26 -> 0.18102473 | D26: =SA_raw_data_2018!H21/SA_raw_data_2018!N13 -> 0.15733252 | E26: =F26+G26 -> 0.02369221 | F26: 0 | G26: =SA_raw_data_2018!H30/SA_raw_data_2018!O19 -> 0.02369221 | H26: =I26+J26 -> 0.65094746 | I26: =(SA_raw_data_2018!D21+SA_raw_data_2018!F21)/SA_raw_data_2018!O19 -> 0.083298872 | J26: =(SA_raw_data_2018!D30+SA_raw_data_2018!F30)/SA_raw_data_2018!O19 -> 0.56764859 | K26: =(SA_raw_data_2018!D31+SA_raw_data_2018!F31)/SA_raw_data_2018!O19 -> 0.5077802 | L26: =J26-K26 -> 0.059868386 | M26: =N26+Q26 -> 0.14432658 | N26: =O26+P26 -> 0.039307568 | O26: =(SA_raw_data_2018!J33+SA_raw_data_2018!L33)/SA_raw_data_2018!O19*(1/3) -> 0.039207568 | P26: 0.0001 | Q26: =R26+S26 -> 0.10501901 | R26: =(SA_raw_data_2018!J21+SA_raw_data_2018!L21)/SA_raw_data_2018!O19 -> 0.021825365 | S26: =(SA_raw_data_2018!J32+SA_raw_data_2018!L32)/SA_raw_data_2018!O19*(2/3) -> 0.083193649 | T26: =(SA_raw_data_2018!J33+SA_raw_data_2018!L33)/SA_raw_data_2018!O19*(2/3) -> 0.078415135 | U26: =SA!S26-SA!T26 -> 0.0047785137 | AA26: =(SA_raw_data_2018!N24+SA_raw_data_2018!N27)/SA_raw_data_2018!O19 -> 0.048729948
A27: SA | B27: 2019
A28: SA | B28: 2020
A29: SA | B29: 2021
A30: SA | B30: 2022
A31: SA | B31: 2023
A32: SA | B32: 2024
A33: SA | B33: 2025

Sheet SA_raw Sheet2
A1: Year | B1: GDP | C1: confc | D1: comhn | E1: Cfcgo | F1: Nsrgo | G1: Ceugo | H1: Cfcco | I1: Nsrco | J1: gsrco | K1: Ceuco | L1: Ceuhn | M1: cfchn | N1: Nmxhn | O1: gmxhn | P1: Ccmhn | Q1: Nsrhn | R1: Ccshn | S1: Ptxgo
A2: 2013 | B2: 2799927 | C2: 240181 | D2: 550298 | E2: 47915 | F2: 0 | G2: 320155 | H2: 180000 | I2: 1646607 | J2: 1820000 | K2: 188600 | L2: 41500 | M2: 12350 | N2: 333105 | O2: 345291 | P2: =O2-N2 -> 12186 | Q2: 0 | R2: =M2-P2 -> 164 | S2: 21174
A3: 2014 | B3: 2836314 | C3: 257899 | D3: 580386 | E3: 54704 | F3: 0 | G3: 336832 | H3: 191000 | I3: 1599761 | J3: 1790000 | K3: 190000 | L3: 43300 | M3: 12930 | N3: 365096 | O3: 377878 | P3: =O3-N3 -> 12782 | Q3: 0 | R3: =M3-P3 -> 148 | S3: 23520
A4: 2015 | B4: 2453512 | C4: 310729 | D4: 682287 | E4: 61369 | F4: 0 | G4: 413698 | H4: 232329 | I4: 1048998 | J4: 1281000 | K4: 218000 | L4: 49000 | M4: 17030 | N4: 377697 | O4: 394522 | P4: =O4-N4 -> 16825 | Q4: 0 | R4: =M4-P4 -> 205 | S4: 25995
S6: SUM | T6: SUM
A7: Year | B7: GDP | C7: confc | D7: comhn | E7: Cfcgo | F7: Nsrgo | G7: Ceugo | H7: Cfcco | I7: Nsrco | J7: gsrco | K7: Ceuco | L7: Ceuhn | M7: cfchn | N7: Nmxhn | O7: gmxhn | P7: Ccmhn | Q7: Nsrhn | R7: Ccshn | S7: Ptxgo
A8: 2013 | B8: =B2/$B2 -> 1 | C8: =C2/$B2 -> 0.085781165 | D8: =D2/$B2 -> 0.19654012 | E8: =E2/$B2 -> 0.017112946 | F8: =F2/$B2 -> 0 | G8: =G2/$B2 -> 0.11434405 | H8: =H2/$B2 -> 0.06428739 | I8: =I2/$B2 -> 0.58808926 | ... S8: =S2/$B2 -> 0.00756234 | T8: =S8+O8+J8+D8+E8 -> 0.99455379 | U8: =C8+D8+I8+N8+S8 -> 0.99694206
A9: 2014 | B9: =B3/$B3 -> 1 | C9: =C3/$B3 -> 0.090927521 | D9: =D3/$B3 -> 0.20462685 | E9: =E3/$B3 -> 0.019287004 | F9: =F3/$B3 -> 0 | G9: =G3/$B3 -> 0.11875695 | H9: =H3/$B3 -> 0.067340922 | I9: =I3/$B3 -> 0.56402817 | ... S9: =S3/$B3 -> 0.0082924528 | T9: =S9+O9+J9+D9+E9 -> 0.99653564 | U9: =C9+D9+I9+N9+S9 -> 0.99659699
A10: 2015 | B10: =B4/$B4 -> 1 | C10: =C4/$B4 -> 0.12664662 | D10: =D4/$B4 -> 0.27808586 | E10: =E4/$B4 -> 0.025012716 | F10: =F4/$B4 -> 0 | G10: =G4/$B4 -> 0.16861462 | H10: =H4/$B4 -> 0.094692425 | I10: =I4/$B4 -> 0.42754957 | ... S10: =S4/$B4 -> 0.010595016 | T10: =S10+O10+J10+D10+E10 -> 0.9966012 | U10: =C10+D10+I10+N10+S10 -> 0.99681844
B12: GO | C12: HN | D12: CO | E12: ptxgo | F12: SUM
A13: 2013 | B13: =E8+G8 -> 0.131457 | C13: =N8+P8+Q8+R8+L8 -> 0.13820182 | D13: =K8+I8+H8 -> 0.71973555 | E13: =S8 -> 0.00756234 | F13: =B13+C13+D13+E13 -> 0.99695671
A14: 2014 | B14: =E9+G9 -> 0.13804395 | C14: =N9+P9+Q9+R9+L9 -> 0.14854702 | D14: =K9+I9+H9 -> 0.69835745 | E14: =S9 -> 0.0082924528 | F14: =B14+C14+D14+E14 -> 0.99324088 | K14: Sources | L14: 2013-2015: https://www.stats.gov.sa/sites/default/files/national_accounts_in_saudi_arabia_2013_-_2015_according_to_sna2008en.pdf
A15: 2015 | B15: =E10+G10 -> 0.19362734 | C15: =N10+P10+Q10+R10+L10 -> 0.18085381 | D15: =K10+I10+H10 -> 0.61109422 | E15: =S10 -> 0.010595016 | F15: =B15+C15+D15+E15 -> 0.99617039 | M15: https://database.stats.gov.sa/home/indicator/434
K16: manually typed from pdf

Sheet SA_raw_data_2018
A3: Total Economy Account 2018
A4: (Million of Saudi Riyals)
A5: Account | B5: Code | C5: Transaction | D5: Non-financial | F5: Financial | H5: Government | J5: Households | L5: Non-profit institutions serving households | N5: Total Economy | P5: Rest of the world | R5: Total
D6: S.11 | F6: S.12 | H6: S.13 | J6: S.14 | L6: S.15 | N6: S.1 | P6: S.2 | R6: S
D7: Debtor ( Uses ) | E7: Creditor ( Resources ) | F7: Debtor ( Uses ) | G7: Creditor ( Resources ) | H7: Debtor ( Uses ) | I7: Creditor ( Resources ) | J7: Debtor ( Uses ) | K7: Creditor ( Resources ) | L7: Debtor ( Uses ) | M7: Creditor ( Resources ) | N7: Debtor ( Uses ) | O7: Creditor ( Resources ) | P7: Debtor ( Uses ) | Q7: Creditor ( Resources ) | R7: Debtor ( Uses ) | S7: Creditor ( Resources )
A8: External Account of Goods and Services | B8: P.6 | C8: Exports of goods and services | N8: 0 | O8: 0 | P8: 1180937.2 | Q8: 0 | R8: 0 | S8: 1180937.2
B9: P.7 | C9: Imports of goods and services | N9: 0 | O9: 0 | P9: 0 | Q9: 785960.23 | R9: 785960.23 | S9: 0 | U9: Corporate capital share
A10: Account I : Production account | B10: P.1 | C10: Output | D10: 0 | E10: 3435297.2 | F10: 0 | G10: 113270.38 | H10: 0 | I10: 759085.56 | J10: 0 | K10: 724007.52 | L10: 0 | M10: 5037 | N10: 0 | O10: 5036697.7 | R10: 0 | S10: 5036697.7
B11: P.2 | C11: Intermediate consumption | D11: 1459585.8 | E11: 0 | F11: 14219.016 | G11: 0 | H11: 199727.84 | I11: 0 | J11: 272046.09 | K11: 0 | L11: 1167 | M11: 0 | N11: 1946745.7 | O11: 0 | R11: 1946745.7 | S11: 0
B12: D.21-D.31 | C12: Taxes less subsidies on products | D12: 0 | E12: 0 | F12: 0 | G12: 0 | H12: 0 | I12: 0 | J12: 0 | K12: 0 | L12: 0 | M12: 0 | N12: 0 | O12: 84737.237 | R12: 0 | S12: 84737.237
B13: B.1g | C13: Gross domestic product/ Value added, Gross | D13: 1975711.5 | E13: 0 | F13: 99051.365 | G13: 0 | H13: 559357.72 | I13: 0 | J13: 451961.43 | K13: 0 | L13: 3870 | M13: 0 | N13: 3089952 | O13: 0 | R13: 3089952 | S13: 0
B14: P.51c | C14: Consumption of fixed capital | D14: 182224.17 | E14: 0 | F14: 2766.267 | G14: 0 | H14: 73207.79 | I14: 0 | J14: 22148.067 | K14: 0 | L14: 326 | M14: 0 | N14: 280672.29 | O14: 0 | R14: 280672.29 | S14: 0
B15: B.1n | C15: Net domestic product/Value added, Net | D15: 1793487.3 | E15: 0 | F15: 96285.098 | G15: 0 | H15: 486149.93 | I15: 0 | J15: 429813.36 | K15: 0 | L15: 3544 | M15: 0 | N15: 2809279.7 | O15: 0 | R15: 2809279.7 | S15: 0
B16: B.1*g | C16: Gross Domestic Product | N16: 3174689.2 | O16: 0 | R16: 3174689.2 | S16: 0
B17: B.11 | C17: External balance of goods and services | N17: 0 | O17: 0 | P17: -394976.96 | R17: 0 | S17: -394976.96
A18: Account II.1.1 : Generation of income account | B18: B.11 | C18: External balance of goods and services | N18: 0 | O18: 0 | Q18: -394976.96 | R18: -394976.96 | S18: 0
B19: B.1g | C19: Value added, Gross/Gross domestic product | D19: 0 | E19: 1975711.5 | F19: 0 | G19: 99051.365 | H19: 0 | I19: 559357.72 | J19: 0 | K19: 451961.43 | L19: 0 | M19: 3870 | N19: 0 | O19: 3089952 | R19: 0 | S19: 3089952
B20: B.1n | C20: Net domestic product/ Value added, Net | D20: 0 | E20: 1793487.3 | F20: 0 | G20: 96285.098 | H20: 0 | I20: 486149.93 | J20: 0 | K20: 429813.36 | L20: 0 | M20: 3544 | N20: 0 | O20: 2809279.7 | R20: 0 | S20: 2809279.7
B21: D.1 | C21: Compensation of employees | D21: 234830.26 | E21: 0 | F21: 22559.249 | G21: 0 | H21: 486149.93 | I21: 0 | J21: 63895.331 | K21: 0 | L21: 3544 | M21: 0 | N21: 810978.77 | O21: 0 | R21: 810978.77 | S21: 0
B22: D.11 | C22: Wages and salaries | D22: 189065.01 | E22: 0 | F22: 18114.526 | G22: 0 | H22: 453331.61 | I22: 0 | J22: 62019.188 | K22: 0 | L22: 3366 | M22: 0 | N22: 725896.33 | O22: 0 | R22: 725896.33 | S22: 0
B23: D.12 | C23: Employers social contributions | D23: 45765.255 | E23: 0 | F23: 4444.7234 | G23: 0 | H23: 32818.321 | I23: 0 | J23: 1876.1434 | K23: 0 | L23: 178 | M23: 0 | N23: 85082.443 | O23: 0 | R23: 85082.443 | S23: 0
B24: D.2 | C24: Taxes on production and imports | D24: 64620.371 | F24: 1145.6609 | G24: 0 | H24: 0 | I24: 0 | J24: 3131.9318 | K24: 0 | L24: 0 | M24: 0 | N24: 162060.31 | O24: 0 | R24: 162060.31 | S24: 0
B25: D.21 | C25: Taxes on products | D25: 0 | F25: 0 | G25: 0 | H25: 0 | I25: 0 | J25: 0 | K25: 0 | L25: 0 | M25: 0 | N25: 93162.345 | O25: 0 | R25: 93162.345 | S25: 0
B26: D.29 | C26: Other taxes on production | D26: 64620.371 | E26: 0 | F26: 1145.6609 | G26: 0 | H26: 0 | I26: 0 | J26: 3131.9318 | K26: 0 | L26: 0 | M26: 0 | N26: 68897.963 | O26: 0 | R26: 68897.963 | S26: 0
B27: D.3 | C27: Subsidies | D27: -2399.5928 | E27: 0 | F27: 0 | G27: 0 | H27: 0 | I27: 0 | J27: -662.407 | K27: 0 | L27: 0 | M27: 0 | N27: -11487.108 | O27: 0 | R27: -11487.108 | S27: 0
B28: D.31 | C28: Subsidies on products | D28: 0 | E28: 0 | F28: 0 | G28: 0 | H28: 0 | I28: 0 | J28: 0 | K28: 0 | L28: 0 | M28: 0 | N28: -8425.1082 | O28: 0 | R28: -8425.1082 | S28: 0
B29: D.39 | C29: Other subsidies on production | D29: -2399.5928 | E29: 0 | F29: 0 | G29: 0 | H29: 0 | I29: 0 | J29: -662.407 | K29: 0 | L29: 0 | M29: 0 | N29: -3061.9998 | O29: 0 | R29: -3061.9998 | S29: 0
B30: B.2g | C30: Operating surplus, Gross | D30: 1678660.4 | E30: 0 | F30: 75346.455 | G30: 0 | H30: 73207.79 | I30: 0 | J30: 0 | K30: 0 | L30: 326 | M30: 0 | N30: 1827540.7 | O30: 0 | R30: 1827540.7 | S30: 0
B31: B.2n | C31: Operating surplus, Net | D31: 1496436.3 | E31: 0 | F31: 72580.188 | G31: 0 | H31: 0 | I31: 0 | L31: 0 | M31: 0 | N31: 1569016.4 | O31: 0 | R31: 1569016.4 | S31: 0
B32: B.3g | C32: Mixed incom, Gross | J32: 385596.57 | K32: 0 | N32: 385596.57 | O32: 0 | R32: 385596.57 | S32: 0
B33: B.3n | C33: Mixed incom, Net | J33: 363448.5 | K33: 0 | N33: 363448.5 | O33: 0 | R33: 363448.5 | S33: 0
A34: Account II.1.2 : Allocation of primary income account | B34: B.2g | C34: Operating surplus, Gross | D34: 0 | E34: 1678660.4 | F34: 0 | G34: 75346.455 | H34: 0 | I34: 73207.79 | J34: 0 | K34: 0 | L34: 0 | M34: 326 | N34: 0 | O34: 1827540.7 | R34: 0 | S34: 1827540.7
B35: B.2n | C35: Operating surplus, Net | D35: 0 | E35: 1496436.3 | F35: 0 | G35: 72580.188 | H35: 0 | I35: 0 | J35: 0 | K35: 0 | L35: 0 | M35: 0 | N35: 0 | O35: 1569016.4 | R35: 0 | S35: 1569016.4
B36: B.3g | C36: Mixed incom, Gross | K36: 385596.57 | N36: 0 | O36: 385596.57 | R36: 0 | S36: 385596.57
B37: B.3n | C37: Mixed incom, Net | D37: 0 | E37: 0 | F37: 0 | G37: 0 | H37: 0 | I37: 0 | J37: 0 | K37: 363448.5 | L37: 0 | M37: 0 | N37: 0 | O37: 363448.5 | R37: 0 | S37: 363448.5
B38: D.1 | C38: Compensation of employees | J38: 0 | K38: 808815.65 | N38: 0 | O38: 808815.65 | P38: 1255.93 | Q38: 3419.05 | R38: 3419.05 | S38: 810071.58
B39: D.11 | C39: Wages and salaries | J39: 0 | K39: 723733.21 | N39: 0 | O39: 723733.21 | P39: 1255.93 | Q39: 3419.05 | R39: 3419.05 | S39: 724989.14
B40: D.12 | C40: Employers social contributions | J40: 0 | K40: 85082.443 | N40: 0 | O40: 85082.443 | P40: 0 | Q40: 0 | R40: 0 | S40: 85082.443
B41: D.2 | C41: Taxes on production and imports | H41: 0 | I41: 162060.31 | N41: 0 | O41: 162060.31 | P41: 0 | Q41: 0 | R41: 0 | S41: 162060.31
B42: D.21 | C42: Taxes on products | H42: 0 | I42: 93162.345 | N42: 0 | O42: 93162.345 | P42: 0 | Q42: 0 | R42: 0 | S42: 93162.345
...

Sheet SAW_rawReport
B1: Year | I1: Year | Q1: Income Factors | R1: Compensation of Employees | S1: Net Taxes on Production | T1: Consumption of Fixed Capital | U1: Net Operating Surplus | V1: Gross Domestic Product
A2: Income Factors | B2: 2017 | C2: 2018 | D2: 2019 | E2: 2020 | F2: 2021 | G2: 2022 | I2: 2017 | J2: 2018 | K2: 2019 | L2: 2020 | M2: 2021 | N2: 2022 | Q2: 2017 | R2: 0.26538188 | S2: 0.019701032 | T2: 0.10412087 | U2: 0.61079622 | V2: 1
A3: Compensation of Employees | B3: 711549.9 | C3: 810978.77 | D3: 843116.74 | E3: 856682.85 | F3: 931608.68 | G3: 988183.85 | I3: 0.26538188 | J3: 0.25545139 | K3: 0.26811423 | L3: 0.31112315 | M3: 0.28419292 | N3: 0.23770744 | Q3: 2018 | R3: 0.25545139 | S3: 0.047429273 | T3: 0.088409377 | U3: 0.60870996 | V3: 1
A4: Net Taxes on Production | B4: 52823 | C4: 150573.2 | D4: 168270.35 | E4: 160121.81 | F4: 229675.73 | G4: 230892.9 | I4: 0.019701032 | J4: 0.047429273 | K4: 0.05351059 | L4: 0.058151742 | M4: 0.070063985 | N4: 0.055541244 | Q4: 2019 | R4: 0.26811423 | S4: 0.05351059 | T4: 0.094451679 | U4: 0.5839235 | V4: 1
A5: Consumption of Fixed Capital | B5: 279172 | C5: 280672.29 | D5: 297014.42 | E5: 311441.16 | F5: 323719.93 | G5: 349476.67 | I5: 0.10412087 | J5: 0.088409377 | K5: 0.094451679 | L5: 0.11310668 | M5: 0.098752742 | N5: 0.084066546 | Q5: 2020 | R5: 0.31112315 | S5: 0.058151742 | T5: 0.11310668 | U5: 0.51761843 | V5: 1
A6: Net Operating Surplus | B6: 1637685.2 | C6: 1932464.9 | D6: 1836216.1 | E6: 1425271.1 | F6: 1793081.1 | G6: 2588589.8 | I6: 0.61079622 | J6: 0.60870996 | K6: 0.5839235 | L6: 0.51761843 | M6: 0.54699035 | N6: 0.62268477 | Q6: 2021 | R6: 0.28419292 | S6: 0.070063985 | T6: 0.098752742 | U6: 0.54699035 | V6: 1
A7: Gross Domestic Product | B7: 2681230.1 | C7: 3174689.2 | D7: 3144617.6 | E7: 2753516.9 | F7: 3278085.4 | G7: 4157143.2 | I7: 1 | J7: 1 | K7: 1 | L7: 1 | M7: 1 | N7: 1 | Q7: 2022 | R7: 0.23770744 | S7: 0.055541244 | T7: 0.084066546 | U7: 0.62268477 | V7: 1
A11: Metadata | B11: https://database.stats.gov.sa/home/indicator/606
A12: Report name: Gross domestic product (GDP) at current price by income approach
A13: Indicator Code: EFNA0401
A14: Indicator Name: GDP by Income Approach
A15: Data Producer: General Authority for Statistics
A16: Frequency: Annual
A17: Methodology Link: Methodologies/En_Documents/33_Annual National Account Indicators Methodology _ General Authority for Statistics.pdf
A18: Date of Extraction: Mon Dec 16 2024 19:24:27 GMT+0100 (Mitteleuropäische Normalzeit)
A19: Report Link: https://database.stats.gov.sa/home/report/4045

Sheet SA_RAWInstitutional
C1: Year
A2: Item Code | B2: Institutional Sectors | C2: 2010 | D2: 2011 | E2: 2012 | F2: 2013 | G2: 2014 | H2: 2015 | I2: 2016 | J2: 2017 | K2: 2018 | L2: 2019 | M2: 2020 | N2: 2021 | O2: 2022 | P2: 2024
A3: 1 | B3: Oil Sector | C3: 880392.58 | D3: 1276416.4 | E3: 1376577.1 | F3: 1290793.8 | G3: 1197428.5 | H3: 659699.39 | I3: 595540.82 | J3: 735363.05 | K3: 1086260.6 | L3: 958288.37 | M3: 612500.02 | N3: 928650.94 | O3: 1617919.4 | P3: 885561.34
A4: 2 | B4: Non-Oil Sector | C4: 1085716.1 | D4: 1243678.3 | E4: 1383866.3 | F4: 1515024.2 | G4: 1653823.8 | H4: 1824872 | I4: 1876096.7 | J4: 1922489 | K4: 2003691.4 | L4: 2094384.9 | M4: 2023746.9 | N4: 2151580 | O4: 2348160.1 | P4: 1986735.6
A5: 2.1 | B5: Government Sector | C5: 332671.13 | D5: 371169.46 | E5: 413473.06 | F5: 436992.1 | G5: 465787.45 | H5: 554394.58 | I5: 569764.96 | J5: 576257.09 | K5: 645503.61 | L5: 674981.97 | M5: 663347.44 | N5: 667942.6 | O5: 700710.95 | P5: 568854.34
A6: 2.2 | B6: Private Sector | C6: 753044.97 | D6: 872508.8 | E6: 970393.26 | F6: 1078032.1 | G6: 1188036.4 | H6: 1270477.4 | I6: 1306331.8 | J6: 1346231.9 | K6: 1358187.8 | L6: 1419402.9 | M6: 1360399.5 | N6: 1483637.4 | O6: 1647449.1 | P6: 1417881.2
A7: 3 | B7: Gross Value Added | C7: 1966108.7 | D7: 2520094.7 | E7: 2760443.4 | F7: 2805818 | G7: 2851252.3 | H7: 2484571.4 | I7: 2471637.6 | J7: 2657852.1 | K7: 3089952 | L7: 3052673.2 | M7: 2636246.9 | N7: 3080230.9 | O7: 3966079.4 | P7: 2872296.9
A8: 4 | B8: Net Taxes on Products | C8: 14668.7 | D8: 17285 | E8: 21494 | F8: 21174 | G8: 23520 | H8: 25995 | I8: 25862 | J8: 23378 | K8: 84737.24 | L8: 91944.42 | M8: 117270.03 | N8: 197854.55 | O8: 191063.74 | P8: 172963.31
A9: 5 | B9: Gross Domestic Product | C9: 1980777.4 | D9: 2537379.7 | E9: 2781937.4 | F9: 2826992 | G9: 2874772.3 | H9: 2510566.4 | I9: 2497499.6 | J9: 2681230.1 | K9: 3174689.2 | L9: 3144617.6 | M9: 2753516.9 | N9: 3278085.4 | O9: 4157143.2 | P9: 3045260.2
C12: Year
A13: Item Code | B13: Institutional Sectors | C13: 2010 | D13: 2011 | E13: 2012 | F13: 2013 | G13: 2014 | H13: 2015 | I13: 2016 | J13: 2017 | K13: 2018 | L13: 2019 | M13: 2020 | N13: 2021 | O13: 2022 | P13: 2024
A14: 1 | B14: Oil Sector | C14: 0.44446822 | D14: 0.5030451 | E14: 0.49482677 | F14: 0.4565962 | G14: 0.41652984 | H14: 0.26276914 | I14: 0.23845483 | J14: 0.27426331 | K14: 0.34216282 | L14: 0.30473923 | M14: 0.2224428 | N14: 0.28329065 | O14: 0.38919019 | P14: 0.29079989
A15: 2 | B15: Non-Oil Sector | C15: 0.54812626 | D15: 0.49014276 | E15: 0.49744697 | F15: 0.53591386 | G15: 0.57528864 | H15: 0.72687662 | I15: 0.75119001 | J15: 0.71701755 | K15: 0.63114568 | L15: 0.6660221 | M15: 0.73496801 | N15: 0.65635262 | O15: 0.56484947 | P15: 0.65240256
A16: 2.1 | B16: Government Sector | C16: 0.16794978 | D16: 0.14628062 | E16: 0.14862773 | F16: 0.15457847 | G16: 0.16202586 | H16: 0.2208245 | I16: 0.22813416 | J16: 0.21492265 | K16: 0.20332813 | L16: 0.21464675 | M16: 0.24090916 | N16: 0.20375997 | O16: 0.16855589 | P16: 0.18679991
A17: 2.2 | B17: Private Sector | C17: 0.38017648 | D17: 0.34386214 | E17: 0.34881922 | F17: 0.38133539 | G17: 0.41326278 | H17: 0.50605211 | I17: 0.52305585 | J17: 0.50209489 | K17: 0.42781756 | L17: 0.45137535 | M17: 0.49405886 | N17: 0.45259265 | O17: 0.39629358 | P17: 0.46560265
A18: 3 | B18: Gross Value Added | C18: 0.99259447 | D18: 0.99318785 | E18: 0.99227373 | F18: 0.99251006 | G18: 0.99181848 | H18: 0.98964576 | I18: 0.98964484 | J18: 0.99128087 | K18: 0.9733085 | L18: 0.97076134 | M18: 0.95741082 | N18: 0.93964326 | O18: 0.95403965 | P18: 0.94320245
A19: 4 | B19: Net Taxes on Products | C19: 0.0074055269 | D19: 0.0068121457 | E19: 0.0077262701 | F19: 0.0074899397 | G19: 0.0081815175 | H19: 0.010354237 | I19: 0.010355157 | J19: 0.0087191323 | K19: 0.026691507 | L19: 0.029238664 | M19: 0.042589181 | N19: 0.06035674 | O19: 0.045960346 | P19: 0.056797546
A20: 5 | B20: Gross Domestic Product | C20: 1 | D20: 1 | E20: 1 | F20: 1 | G20: 1 | H20: 1 | I20: 1 | J20: 1 | K20: 1 | L20: 1 | M20: 1 | N20: 1 | O20: 1 | P20: 1
A25: Metadata
A26: Report name: Gross domestic product (GDP) at current price by institutional sectors
A27: Indicator Code: EfNa0101
A28: Indicator Name: Gross Domestic Product-Current prices
A29: Indicator Definition: It expresses the total of final goods and services produced during a certain period of time (usually a year) within the geographical borders of the country, whether that was done by the citizens of the country or foreigners residing in it.
A30: Data Producer: General Authority for Statistics
A31: Frequency: Annual
A32: Methodology Link: Methodologies/En_Documents/34_quarterly national accounts indicators Methodology _ General Authority for Statistics.pdf,Methodologies/En_Documents/33_Annual National Account Indicators Methodology _ General Authority for Statistics.pdf
A33: Date of Extraction: Tue Dec 17 2024 11:15:56 GMT+0100 (Mitteleuropäische Normalzeit)
A34: Report Link: https://database.stats.gov.sa/home/report/147
