Workbook
Name OLE_LINK1: Explanations!$A$9

Sheet SE
C5: Goverment Sector | D5: Components Goverment Sector | H5: Corporate Sector | I5: Components Corporate Sector | M5: Household Sector | N5: Components Household Sector | V5: Total Economy | AB5: Capital Shares
N6: Housing | Q6: Self-employment | V6: compen-sation of employees | W6: Mixed- income and OS | X6: Gross Operating Surplus | Y6: Mixed Income | AG6: Checks
A7: Notes | I7: residual of imputed wages paied by households | N7: Real Estate Gros Surplus | P7: Assume 1% | R7: imputed as share of total compensations of employees. 2/3 of gmxhn / (gmxhn+gsrco) | S7: Imputed labour Income / 0.7 | X7: Total profits (including selfemployment less30% of mixed income)
A8: iso | B8: year | C8: gvago | D8: ceugo | E8: gsrgo | F8: nsrgo | G8: cfcgo | H8: gvaco | I8: ceuco | J8: gsrco | K8: nsrco | L8: cfcco | M8: gvahn | N8: gsrhn | O8: nsrhn | P8: ccshn | Q8: gvmhn | R8: ceuhn | S8: gmxhn | T8: nmxhn | U8: ccmhn | V8: comhn | Y8: gmxhn | Z8: confc | AA8: ptxgo | AB8: cshare | AC8: cshare_gross | AD8: cshare_corp | AE8: chare_corp_gross | AF8: check_sector | AG8: check_total | AH8: check_chares
A9: SE | B9: 1800 | F9: 0 | Z9: =Data!CT8/Data!K8 -> 0.035728484 | AA9: =(Data!K8-Data!AN8)/Data!K8 -> 0.045805909
A10: SE | B10: 1801 | F10: 0 | Z10: =Data!CT9/Data!K9 -> 0.03496984 | AA10: =(Data!K9-Data!AN9)/Data!K9 -> 0.046004732
A11: SE | B11: 1802 | F11: 0 | Z11: =Data!CT10/Data!K10 -> 0.034302731 | AA11: =(Data!K10-Data!AN10)/Data!K10 -> 0.046199733
A12: SE | B12: 1803 | F12: 0 | Z12: =Data!CT11/Data!K11 -> 0.035350974 | AA12: =(Data!K11-Data!AN11)/Data!K11 -> 0.045993514
A13: SE | B13: 1804 | F13: 0 | Z13: =Data!CT12/Data!K12 -> 0.03833599 | AA13: =(Data!K12-Data!AN12)/Data!K12 -> 0.046011788
A14: SE | B14: 1805 | F14: 0 | Z14: =Data!CT13/Data!K13 -> 0.037317483 | AA14: =(Data!K13-Data!AN13)/Data!K13 -> 0.046253893
A15: SE | B15: 1806 | F15: 0 | Z15: =Data!CT14/Data!K14 -> 0.035959416 | AA15: =(Data!K14-Data!AN14)/Data!K14 -> 0.046085832
A16: SE | B16: 1807 | F16: 0 | Z16: =Data!CT15/Data!K15 -> 0.034426121 | AA16: =(Data!K15-Data!AN15)/Data!K15 -> 0.046297559
A17: SE | B17: 1808 | F17: 0 | Z17: =Data!CT16/Data!K16 -> 0.036619401 | AA17: =(Data!K16-Data!AN16)/Data!K16 -> 0.045799878
A18: SE | B18: 1809 | F18: 0 | Z18: =Data!CT17/Data!K17 -> 0.037981201 | AA18: =(Data!K17-Data!AN17)/Data!K17 -> 0.047242647
A19: SE | B19: 1810 | F19: 0 | Z19: =Data!CT18/Data!K18 -> 0.041272628 | AA19: =(Data!K18-Data!AN18)/Data!K18 -> 0.047619042
A20: SE | B20: 1811 | F20: 0 | Z20: =Data!CT19/Data!K19 -> 0.042842098 | AA20: =(Data!K19-Data!AN19)/Data!K19 -> 0.047371776
... A58: SE | B58: 1849 | F58: 0 | Z58: =Data!CT57/Data!K57 -> 0.040772627 | AA58: =(Data!K57-Data!AN57)/Data!K57 -> 0.047813893
A59: SE | B59: 1850 | C59: =E59+F59+D59 -> 0.058151636 | D59: =Data!HI58/Data!K58 -> 0.056546621 | E59: =Data!IC58/Data!K58 -> 0.0016050153 | F59: 0 | G59: =Data!IC58/Data!K58 -> 0.0016050153 | H59: =I59+J59 -> 0.48883867 | I59: =V59-R59-D59 -> 0.34959847 | J59: =X59-N59 -> 0.1392402 | M59: =N59+Q59 -> 0.40683818 | N59: =Data!ID58/Data!K58 -> 0.049936061 | P59: 0.01 | Q59: =R59+S59 -> 0.35690212 | R59: =(1/3)*(S59/(J59+S59))*(V59) -> 0.11000943 | S59: =(Data!HU58/0.7)/Data!K58 -> 0.24689269 | V59: =Data!HK58/Data!K58 -> 0.51615453 | W59: =X59+Y59 -> 0.43606895 | X59: =Data!IE58/Data!K58 - 0.3*Y59 -> 0.18917626 | Y59: =S59 -> 0.24689269 | Z59: =Data!CT58/Data!K58 -> 0.040845746 | AA59: =(Data!K58-Data!AN58)/Data!K58 -> 0.047776527 | AF59: =N59+Q59+H59+C59+AA59 -> 1.001605 | AG59: =V59+X59+AA59+Y59 -> 1
A60: SE | B60: 1851 | C60: =E60+F60+D60 -> 0.060043939 | D60: =Data!HI59/Data!K59 -> 0.058486391 | E60: =Data!IC59/Data!K59 -> 0.0015575481 | F60: 0 | G60: =Data!IC59/Data!K59 -> 0.0015575481 | H60: =I60+J60 -> 0.501028 | I60: =V60-R60-D60 -> 0.344537 | J60: =X60-N60 -> 0.156491 | M60: =N60+Q60 -> 0.39280507 | N60: =Data!ID59/Data!K59 -> 0.049384797 | P60: 0.01 | Q60: =R60+S60 -> 0.34342028 | R60: =(1/3)*(S60/(J60+S60))*(V60) -> 0.10214077 | S60: =(Data!HU59/Data!K59)/0.7 -> 0.2412795 | V60: =Data!HK59/Data!K59 -> 0.50516417 | W60: =X60+Y60 -> 0.4471553 | X60: =Data!IE59/Data!K59 - 0.3*Y60 -> 0.20587579 | Y60: =S60 -> 0.2412795 | Z60: =Data!CT59/Data!K59 -> 0.040437791 | AA60: =(Data!K59-Data!AN59)/Data!K59 -> 0.047680537 | AF60: =N60+Q60+H60+C60+AA60 -> 1.0015575 | AG60: =V60+X60+AA60+Y60 -> 1
A61: SE | B61: 1852 | C61: =E61+F61+D61 -> 0.057908924 | D61: =Data!HI60/Data!K60 -> 0.056349185 | E61: =Data!IC60/Data!K60 -> 0.0015597387 | F61: 0 | G61: =Data!IC60/Data!K60 -> 0.0015597387 | H61: =I61+J61 -> 0.5031434 | I61: =V61-R61-D61 -> 0.34461379 | J61: =X61-N61 -> 0.15852961 | M61: =N61+Q61 -> 0.39271858 | N61: =Data!ID60/Data!K60 -> 0.050110104 | P61: 0.01 | Q61: =R61+S61 -> 0.34260847 | R61: =(1/3)*(S61/(J61+S61))*(V61) -> 0.10103168 | S61: =(Data!HU60/Data!K60)/0.7 -> 0.2415768 | V61: =Data!HK60/Data!K60 -> 0.50199465 | W61: =X61+Y61 -> 0.45021651 | X61: =Data!IE60/Data!K60 - 0.3*Y61 -> 0.20863971 | Y61: =S61 -> 0.2415768 | Z61: =Data!CT60/Data!K60 -> 0.041063533 | AA61: =(Data!K60-Data!AN60)/Data!K60 -> 0.047788839 | AF61: =N61+Q61+H61+C61+AA61 -> 1.0015597 | AG61: =V61+X61+AA61+Y61 -> 1
A62: SE | B62: 1853 | C62: =E62+F62+D62 -> 0.06012682 | D62: =Data!HI61/Data!K61 -> 0.058526779 | E62: =Data!IC61/Data!K61 -> 0.0016000409 | F62: 0 | G62: =Data!IC61/Data!K61 -> 0.0016000409 | H62: =I62+J62 -> 0.50633905 | I62: =V62-R62-D62 -> 0.34220155 | J62: =X62-N62 -> 0.1641375 | M62: =N62+Q62 -> 0.38745784 | N62: =Data!ID61/Data!K61 -> 0.051070033 | P62: 0.01 | Q62: =R62+S62 -> 0.33638781 | R62: =(1/3)*(S62/(J62+S62))*(V62) -> 0.09846745 | S62: =(Data!HU61/Data!K61)/0.7 -> 0.23792036 | V62: =Data!HK61/Data!K61 -> 0.49919578 | W62: =X62+Y62 -> 0.45312789 | X62: =Data!IE61/Data!K61 - 0.3*Y62 -> 0.21520754 | Y62: =S62 -> 0.23792036 | Z62: =Data!CT61/Data!K61 -> 0.042419454 | AA62: =(Data!K61-Data!AN61)/Data!K61 -> 0.047676333 | AF62: =N62+Q62+H62+C62+AA62 -> 1.0016 | AG62: =V62+X62+AA62+Y62 -> 1
A63: SE | B63: 1854 | C63: =E63+F63+D63 -> 0.051563089 | D63: =Data!HI62/Data!K62 -> 0.049986988 | E63: =Data!IC62/Data!K62 -> 0.0015761005 | F63: 0 | G63: =Data!IC62/Data!K62 -> 0.0015761005 | H63: =I63+J63 -> 0.54651564 | I63: =V63-R63-D63 -> 0.33729198 | J63: =X63-N63 -> 0.20922366 | M63: =N63+Q63 -> 0.35538663 | N63: =Data!ID62/Data!K62 -> 0.051101529 | P63: 0.01 | Q63: =R63+S63 -> 0.3042851 | R63: =(1/3)*(S63/(J63+S63))*(V63) -> 0.080584794 | S63: =(Data!HU62/Data!K62)/0.7 -> 0.22370031 | V63: =Data!HK62/Data!K62 -> 0.46786376 | W63: =X63+Y63 -> 0.4840255 | X63: =Data!IE62/Data!K62 - 0.3*Y63 -> 0.26032519 | Y63: =S63 -> 0.22370031 | Z63: =Data!CT62/Data!K62 -> 0.041926581 | AA63: =(Data!K62-Data!AN62)/Data!K62 -> 0.04811074 | AF63: =N63+Q63+H63+C63+AA63 -> 1.0015761 | AG63: =V63+X63+AA63+Y63 -> 1
A64: SE | B64: 1855 | C64: =E64+F64+D64 -> 0.049113772 | D64: =Data!HI63/Data!K63 -> 0.047405755 | E64: =Data!IC63/Data!K63 -> 0.0017080172 | F64: 0 | G64: =Data!IC63/Data!K63 -> 0.0017080172 | H64: =I64+J64 -> 0.50251121 | I64: =V64-R64-D64 -> 0.35383005 | J64: =X64-N64 -> 0.14868116 | M64: =N64+Q64 -> 0.40184805 | N64: =Data!ID63/Data!K63 -> 0.054315388 | P64: 0.01 | Q64: =R64+S64 -> 0.34753266 | R64: =(1/3)*(S64/(J64+S64))*(V64) -> 0.10459611 | S64: =(Data!HU63/Data!K63)/0.7 -> 0.24293656 | V64: =Data!HK63/Data!K63 -> 0.50583191 | W64: =X64+Y64 -> 0.4459331 | X64: =Data!IE63/Data!K63 - 0.3*Y64 -> 0.20299654 | Y64: =S64 -> 0.24293656 | Z64: =Data!CT63/Data!K63 -> 0.046550427 | AA64: =(Data!K63-Data!AN63)/Data!K63 -> 0.048234985 | AF64: =N64+Q64+H64+C64+AA64 -> 1.001708 | AG64: =V64+X64+AA64+Y64 -> 1
A65: SE | B65: 1856 | C65: =E65+F65+D65 -> 0.04412007 | D65: =Data!HI64/Data!K64 -> 0.042471109 | E65: =Data!IC64/Data!K64 -> 0.001648962 | F65: 0 | G65: =Data!IC64/Data!K64 -> 0.001648962 | H65: =I65+J65 -> 0.52684628 | I65: =V65-R65-D65 -> 0.34859726 | J65: =X65-N65 -> 0.17824902 | M65: =N65+Q65 -> 0.38219432 | N65: =Data!ID64/Data!K64 -> 0.055012986 | P65: 0.01 | Q65: =R65+S65 -> 0.32718133 | R65: =(1/3)*(S65/(J65+S65))*(V65) -> 0.091589351 | S65: =(Data!HU64/Data!K64)/0.7 -> 0.23559198 | V65: =Data!HK64/Data!K64 -> 0.48265772 | W65: =X65+Y65 -> 0.46885399 | X65: =Data!IE64/Data!K64 - 0.3*Y65 -> 0.23326201 | Y65: =S65 -> 0.23559198 | Z65: =Data!CT64/Data!K64 -> 0.046832265 | AA65: =(Data!K64-Data!AN64)/Data!K64 -> 0.048488297 | AF65: =N65+Q65+H65+C65+AA65 -> 1.001649 | AG65: =V65+X65+AA65+Y65 -> 1
A66: SE | B66: 1857 | C66: =E66+F66+D66 -> 0.043212722 | D66: =Data!HI65/Data!K65 -> 0.04146051 | E66: =Data!IC65/Data!K65 -> 0.0017522117 | F66: 0 | G66: =Data!IC65/Data!K65 -> 0.0017522117 | H66: =I66+J66 -> 0.50278204 | I66: =V66-R66-D66 -> 0.34885685 | J66: =X66-N66 -> 0.15392519 | M66: =N66+Q66 -> 0.40722312 | N66: =Data!ID65/Data!K65 -> 0.062802126 | P66: 0.01 | Q66: =R66+S66 -> 0.344421 | R66: =(1/3)*(S66/(J66+S66))*(V66) -> 0.10029816 | S66: =(Data!HU65/Data!K65)/0.7 -> 0.24412284 | V66: =Data!HK65/Data!K65 -> 0.49061552 | W66: =X66+Y66 -> 0.46085016 | X66: =Data!IE65/Data!K65 - 0.3*Y66 -> 0.21672732 | Y66: =S66 -> 0.24412284 | Z66: =Data!CT65/Data!K65 -> 0.050926999 | AA66: =(Data!K65-Data!AN65)/Data!K65 -> 0.048534324 | AF66: =N66+Q66+H66+C66+AA66 -> 1.0017522 | AG66: =V66+X66+AA66+Y66 -> 1
A67: SE | B67: 1858 | C67: =E67+F67+D67 -> 0.05024047 | D67: =Data!HI66/Data!K66 -> 0.048612705 | E67: =Data!IC66/Data!K66 -> 0.001627765 | F67: 0 | G67: =Data!IC66/Data!K66 -> 0.001627765 | H67: =I67+J67 -> 0.51095248 | I67: =V67-R67-D67 -> 0.34270622 | J67: =X67-N67 -> 0.16824626 | M67: =N67+Q67 -> 0.39225698 | N67: =Data!ID66/Data!K66 -> 0.059723717 | P67: 0.01 | Q67: =R67+S67 -> 0.33253326 | R67: =(1/3)*(S67/(J67+S67))*(V67) -> 0.09488975 | S67: =(Data!HU66/Data!K66)/0.7 -> 0.23764351 | V67: =Data!HK66/Data!K66 -> 0.48620867 | W67: =X67+Y67 -> 0.46561349 | X67: =Data!IE66/Data!K66 - 0.3*Y67 -> 0.22796998 | Y67: =S67 -> 0.23764351 | Z67: =Data!CT66/Data!K66 -> 0.049153319 | AA67: =(Data!K66-Data!AN66)/Data!K66 -> 0.048177832 | AF67: =N67+Q67+H67+C67+AA67 -> 1.0016278 | AG67: =V67+X67+AA67+Y67 -> 1
A68: SE | B68: 1859 | C68: =E68+F68+D68 -> 0.051409895 | D68: =Data!HI67/Data!K67 -> 0.049765833 | E68: =Data!IC67/Data!K67 -> 0.0016440621 | F68: 0 | G68: =Data!IC67/Data!K67 -> 0.0016440621 | H68: =I68+J68 -> 0.49812247 | I68: =V68-R68-D68 -> 0.34343646 | J68: =X68-N68 -> 0.15468601 | M68: =N68+Q68 -> 0.40399319 | N68: =Data!ID67/Data!K67 -> 0.062741827 | P68: 0.01 | Q68: =R68+S68 -> 0.34125136 | R68: =(1/3)*(S68/(J68+S68))*(V68) -> 0.10017949 | S68: =(Data!HU67/Data!K67)/0.7 -> 0.24107187 | V68: =Data!HK67/Data!K67 -> 0.49338178 | W68: =X68+Y68 -> 0.4584997 | X68: =Data!IE67/Data!K67 - 0.3*Y68 -> 0.21742783 | Y68: =S68 -> 0.24107187 | Z68: =Data!CT67/Data!K67 -> 0.050368957 | AA68: =(Data!K67-Data!AN67)/Data!K67 -> 0.048118511 | AF68: =N68+Q68+H68+C68+AA68 -> 1.0016441 | AG68: =V68+X68+AA68+Y68 -> 1
A69: SE | B69: 1860 | C69: =E69+F69+D69 -> 0.05106436 | D69: =Data!HI68/Data!K68 -> 0.049440186 | E69: =Data!IC68/Data!K68 -> 0.0016241738 | F69: 0 | G69: =Data!IC68/Data!K68 -> 0.0016241738 | H69: =I69+J69 -> 0.48775363 | I69: =V69-R69-D69 -> 0.34541282 | J69: =X69-N69 -> 0.14234081 | M69: =N69+Q69 -> 0.41467014 | N69: =Data!ID68/Data!K68 -> 0.063463692 | P69: 0.01 | Q69: =R69+S69 -> 0.35120645 | R69: =(1/3)*(S69/(J69+S69))*(V69) -> 0.10561161 | S69: =(Data!HU68/Data!K68)/0.7 -> 0.24559484 | V69: =Data!HK68/Data!K68 -> 0.50046462 | W69: =X69+Y69 -> 0.45139934 | X69: =Data!IE68/Data!K68 - 0.3*Y69 -> 0.2058045 | Y69: =S69 -> 0.24559484 | Z69: =Data!CT68/Data!K68 -> 0.050335017 | AA69: =(Data!K68-Data!AN68)/Data!K68 -> 0.048136039 | AF69: =N69+Q69+H69+C69+AA69 -> 1.0016242 | AG69: =V69+X69+AA69+Y69 -> 1
A70: SE | B70: 1861 | C70: =E70+F70+D70 -> 0.050518956 | D70: =Data!HI69/Data!K69 -> 0.048900151 | E70: =Data!IC69/Data!K69 -> 0.0016188052 | F70: 0 | G70: =Data!IC69/Data!K69 -> 0.0016188052 | H70: =I70+J70 -> 0.49091234 | I70: =V70-R70-D70 -> 0.34675698 | J70: =X70-N70 -> 0.14415536 | M70: =N70+Q70 -> 0.41202381 | N70: =Data!ID69/Data!K69 -> 0.061964875 | P70: 0.01 | Q70: =R70+S70 -> 0.35005893 | R70: =(1/3)*(S70/(J70+S70))*(V70) -> 0.10507942 | S70: =(Data!HU69/Data!K69)/0.7 -> 0.24497951 | V70: =Data!HK69/Data!K69 -> 0.50073655 | W70: =X70+Y70 -> 0.45109975 | X70: =Data!IE69/Data!K69 - 0.3*Y70 -> 0.20612023 | Y70: =S70 -> 0.24497951 | Z70: =Data!CT69/Data!K69 -> 0.050253374 | AA70: =(Data!K69-Data!AN69)/Data!K69 -> 0.048163705 | AF70: =N70+Q70+H70+C70+AA70 -> 1.0016188 | AG70: =V70+X70+AA70+Y70 -> 1
A71: SE | B71: 1862 | C71: =E71+F71+D71 -> 0.051194519 | D71: =Data!HI70/Data!K70 -> 0.049478301 | E71: =Data!IC70/Data!K70 -> 0.0017162175 | F71: 0 | G71: =Data!IC70/Data!K70 -> 0.0017162175 | H71: =I71+J71 -> 0.48477802 | I71: =V71-R71-D71 -> 0.34164877 | J71: =X71-N71 -> 0.14312925 | M71: =N71+Q71 -> 0.4174708 | N71: =Data!ID70/Data!K70 -> 0.068645851 | P71: 0.01 | Q71: =R71+S71 -> 0.34882495 | R71: =(1/3)*(S71/(J71+S71))*(V71) -> 0.10416132 | S71: =(Data!HU70/Data!K70)/0.7 -> 0.24466363 | V71: =Data!HK70/Data!K70 -> 0.49528839 | W71: =X71+Y71 -> 0.45643873 | X71: =Data!IE70/Data!K70 - 0.3*Y71 -> 0.2117751 | Y71: =S71 -> 0.24466363 | Z71: =Data!CT70/Data!K70 -> 0.054241665 | AA71: =(Data!K70-Data!AN70)/Data!K70 -> 0.048272876 | AF71: =N71+Q71+H71+C71+AA71 -> 1.0017162 | AG71: =V71+X71+AA71+Y71 -> 1
... A209: SE | B209: 2000 | C209: =E209+F209+D209 -> 0.18370779 | D209: =Data!HI208/Data!K208 -> 0.16905019 | E209: =Data!IC208/Data!K208 -> 0.014657594 | F209: 0 | G209: =Data!IC208/Data!K208 -> 0.014657594 | H209: =I209+J209 -> 0.50387532 | I209: =V209-R209-D209 -> 0.36312009 | J209: =X209-N209 -> 0.14075523 | M209: =N209+Q209 -> 0.22802853 | N209: =Data!ID208/Data!K208 -> 0.09734915 | P209: 0.01 | Q209: =R209+S209 -> 0.13067938 | R209: =(1/3)*(S209/(J209+S209))*(V209) -> 0.063921686 | S209: =(Data!HU208/Data!K208)/0.7 -> 0.066757699 | V209: =Data!HK208/Data!K208 -> 0.59609197 | W209: =X209+Y209 -> 0.30486208 | X209: =Data!IE208/Data!K208 - 0.3*Y209 -> 0.23810438 | Y209: =S209 -> 0.066757699 | Z209: =Data!CT208/Data!K208 -> 0.12519403 | AA209: =(Data!K208-Data!AN208)/Data!K208 -> 0.099045951 | AF209: =N209+Q209+H209+C209+AA209 -> 1.0146576 | AG209: =V209+X209+AA209+Y209 -> 1
A210: SE | B210: 2001
A211: SE | B211: 2002
A212: SE | B212: 2003
A213: SE | B213: 2004
A214: SE | B214: 2005
A215: SE | B215: 2006
A216: SE | B216: 2007
A217: SE | B217: 2008
A218: SE | B218: 2009
...

Sheet Data
A1: File name (filnamn): Historical national accounts for Sweden 1800-2000 (Historiska nationalräkenskaper för Sverige 1800-2000) Version 1.0 Last updated (senast uppdaterad): 050404
A2: Author (författare): Rodney Edvinsson | CT2: confc | HV2: Mixed income = imputed self-employed labour income / 0.7
A4: A. Annual volume growth (in percent) of aggregate production according to different estimates. | J4: B. Current values (in million SEK) of some aggregate variables. | U4: C. Estimates of GDP per capita and population | AE4: D. Nominal gross value added (in basic prices, million SEK) of different types of activities and of GDP. | AP4: E. Annual growth rates (in percent) of the volume gross value added (in basic prices and corrected for changes in the value added share in gross output) of different types of activities. | BA4: F. Nominal values (in purchasers’ prices, million SEK) of different expenditures and of GDP by expenditure. | BL4: G. Annual volume growth rates (in percent) of various expenditures and of GDP by expenditure (based on purchasers’ prices). | BT4: H. Annual changes (in percent) in the prices indices (purchasers’ prices) of various expenditures and of GDP by expenditure. | CB4: I. Nominal value of gross investment (in purchasers’ prices, million SEK) of various types of activities and total gross investment. | CL4: J. Consumption of fixed assets (in current, purchasers’ prices, million SEK) of various types of activities and total consumption of fixed assets | CV4: K. Net (capacity) stock of various types of produced assets (in current, purchasers’ prices, million SEK), aggregate economy, and the total net stock of produced assets of the aggregate economy, of the private sector and of manufacturing and handicrafts (1st of January each year) | DF4: L. Annual volume growth rates (in percent) of the net (capacity) stock of various types of produced assets (based on purchasers’ prices), aggregate economy, and of the total net stock of produced assets of the aggregate economy, of the private sector and of manufacturing and handicrafts | DQ4: M. Gross (capacity) stock of various types of produced assets (current, purchasers’ prices, million SEK), aggregate economy, and the total gross stock of produced assets of the aggregate economy, of the private sector and of manufacturing and handicrafts (1st of January each year) | EA4: N. Annual volume growth rates (in percent) of the gross (capacity) stock of various types of produced assets (purchasers’ prices, million SEK), aggregate economy, and of the total gross stock of produced assets of the aggregate economy, of the private sector and of manufacturing and handicrafts | EL4: O. Number of employed (employees and self-employed) of various types of activities | EX4: P. Number of employees of various types of activities | FJ4: Q. Number of self-employed of various types of activities, and the number of “housewives” | FU4: R. Total hours worked (in tens of thousands) of employed (employees and self-employed) of different types of activities | GG4: S. Total hours worked (in tens of thousands) of employees of different types of activities | GS4: T. Total hours worked (in tens of thousands) of self-employed of different types of activities | HC4: U. Wages and salaries (including social benefits) of employees (current factor values, million SEK) of various types of activities. | HN4: V. Imputed labour income of self-employed (including social benefits, current factor values, million SEK) of various types of activities. | HW4: W. Gross surplus (current, basic values, million SEK) of various types of activities. | IH4: X. Various ratios (in percent, based on current purchasers’ and purchasers’ proxy prices) and annual change in real wage rate (in percent) for manufacturing and handicrafts.
A5: A. Årliga volymtillväxt (i procent) av den aggregerade produktion enligt olika mått | J5: B. Olika aggregerade variabler till löpande pris (i miljoner kronor) | U5: C. Skattningar av BNP per capita och befolkning | AE5: D. Bruttoförädlingsvärdet (till löpande baspris, miljoner kronor) för olika branscher och för BNP | AP5: E. Årlig tillväxt (i procent) av volymvärdet för bruttoförädlingsvärdet (till baspris och korrigerad för förändringar i förädlingsvärdets andel av bruttoprodukten) för olika branscher | BA5: F. Löpande värde (till mottagarpriser, miljoner kronor) av olika användningar och BNP från användningssidan | BL5: G. Årliga volymtillväxt (i procent) för olika användningar och BNP från användningssidan (baserat på mottagarpriser) | BT5: H. Årliga förändring (i procent) i prisindex (mottagarpriser) för olika användingar och BNP från användningssidan | CB5: I. Löpande värde av bruttoinvesteringar (till mottagarpris, miljoner kronor) inom olika branscher och totala bruttoinvesteringar | CL5: J. Avskrivningar av fasta tillgångar (i löpander mottagarpriser, miljoner kronor) för olika branscher och totala avskrivningar av fasta tillgångar | CV5: K. Netto(kapacitets)stocken av olika typer av producerade tillgångar (till löpande mottagarpriser, miljoner kronor), hela ekonomin, och den totala nettostocken av producerade tillgångar för hela ekonomin, för privata sektorn och för industri och hantverk (första januari varje år) | DF5: L. Årliga volymtillväxt (i procent) för netto(kapacitets)stocken av olika typer av producerade tillgångar (baserat på mottagarpriser), hela ekonomin, och för den totala nettostocken av producerade tillgångar för hela ekonomin, för privata sektorn och för industri och hantverk (första januari varje år) | DQ5: M. Brutto(kapacitets)stocken av olika typer av producerade tillgångar (till löpande mottagarpriser, miljoner kronor), hela ekonomin, och den totala bruttostocken av producerade tillgångar för hela ekonomin, för privata sektorn och för industri och hantverk (första januari varje år) | EA5: N. Årlig volymtillväxt för brutto(kapacitets)stocken av olika typer av producerade tillgångar (till löpande mottagarpriser, miljoner kronor), hela ekonomin, och för den totala bruttostocken av producerade tillgångar för hela ekonomin, för privata sektorn och för industri och hantverk (första januari varje år) | EL5: O. Antal sysselsatta (anställda och företagare) inom olika branscher | EX5: P. Antal anställda inom olika branscher | FJ5: Q. Antal företagare inom olika branscher, och antalet "hemmafruar" | FU5: R. Totala antalet arbetade timmar (i 10000-tals) för sysselsatta (anställda och företagare) inom olika branscher | GG5: S. Totala antalet arbetade timmar (i 10000-tals) för anställda inom olika branscher | GS5: T. Totala antalet arbetade timmar (i 10000-tals) för företagare inom olika branscher | HC5: U. Löner (inklusive sociala avgifter) för anställda (till löpande faktorvärden, miljoner kronor) inom olika branscher | HN5: V. Tillskriven arbetsinkomst för företagare (inklusive sociala avgifter, till löpande faktorvärden, miljoner kronor) inom olika branscher | HW5: W. Bruttoöverskott (löpande basvärden, miljoner kronor) inom olika branscher | IH5: X. Olika kvoter (i procent, baserat på löpande mottagarpriser och tillskrivna mottagarpriser) och årlig förändring i reallön (i procent) inom industri och hantverk.
A6: Annual change | B6: Gross Domestic Product (GDP) by activity, Fisher index, corrected for changes in the share of value added in gross output, based on basic prices | C6: Net Domestic Product (NDP) by activity, corrected for changes in the share of value added in gross output, based on basic prices | D6: Gross Domestic Product (GDP) by activity, Laspeyre volume index, corrected for changes in the share of value added in gross output, based on basic prices | E6: Gross Domestic Product (GDP) by activity, Paasche volume index, corrected for changes in the share of value added in gross output, based on basic prices | F6: Gross Domestic Product (GDP) by activity, Fisher, uncorrected for changes in the share of value added in gross output, based on basic prices | G6: Gross Domestic Product (GDP) by expenditure, Fisher index, based on purchasers' prices | H6: Net National Product (NDP) by expenditure, Fisher index, based on purchasers' prices | J6: Year | K6: GDP by expenditure, purchasers' prices | L6: GDP by activity, basic prices | M6: NDP by expenditure, purchasers' prices | N6: NDP by activity, basic prices | O6: Consumption of fixed assets, purchasers' prices | P6: Purchasers' value less basic value of GDP | Q6: Intermediate consumption, purchasers' prices | R6: Gross Domestic Output, purchasers' prices | S6: Gross Domestic Output, basic prices | U6: Year | V6: GDP per capita by expenditure in purchasers' prices (SEK), nominal value | W6: GDP per capita by expenditure in purchasers' prices (SEK), volume value (reference year 2000) | X6: Volume growth from preceding year (%) of GDP per capita by expenditure in purchasers' prices (SEK) | Y6: GDP per capita by activity in basic prices (SEK), löpande värden | Z6: GDP per capita by activity in basic prices (SEK), volume value (reference year 2000) | AA6: Volume growth from preceding year (%) of GDP per capita by activity in basic prices (SEK), volume value (reference year 2000) | AB6: Mean population | AC6: Population growth | AE6: Year | AF6: Agriculture and ancillaries | AG6: Manufacturing and handicrafts | AH6: Building and construction | AI6: Transport and communication | AJ6: Circulation | AK6: Private reproductive services* | AL6: Government services | AM6: Real estate | AN6: GDP by activity | AP6: Annual change | AQ6: Agriculture and ancillaries | AR6: Manufacturing and handicrafts | AS6: Building and construction | AT6: Transport and communication | AU6: Circulation* | AV6: Private reproductive services* | AW6: Government services | AX6: Real estate | AY6: GDP | BA6: Year | BB6: Private final consumption | BC6: Government final consumption | BD6: Investment in buildings and structures | BE6: Investment in machinery and equipment | BF6: Changes in fixed livestock | BG6: Changes in inventory stock | BH6: Export | BI6: Import | BJ6: GDP | BL6: Annual change | BM6: Private final consumption | BN6: Government final consumption | BO6: Investment | BP6: Export | BQ6: Import | BR6: GDP | BT6: Annual change | BU6: Private final consumption | BV6: Government final consumption | BW6: Investment | BX6: Export | BY6: Import | BZ6: GDP | CB6: Year | CC6: Agriculture and ancillaries | CD6: Manufacturing and handicrafts | CE6: Building and construction | CF6: Transport and communication | CG6: Other private services, here include circulation (code CC), private reproductive services (code PR) and letting of other premises | CH6: Government services | CI6: Services of dwellings | CJ6: Total gross investment | CL6: Year | CM6: Agriculture and ancillaries | CN6: Manufacturing and handicrafts | CO6: Building and construction | CP6: Transport and communication | CQ6: Other private services, here include circulation (code CC), private reproductive services (code PR) and letting of other premises | CR6: Government services | CS6: Services of dwellings | CT6: Total consumption of fixed assets | CV6: År | CW6: Residential buildings | CX6: Non-residential structures et al. | CY6: Machinery and equipment | CZ6: Fixed livestock | DA6: Inventory stock | DB6: Total, aggregate economy | DC6: Total, private sector | DD6: Total, manufacturing and handicrafts | DF6: During year | DG6: Buildings and structures | DH6: Residential buildings | DI6: Non-residential structures et al. | DJ6: Machinery and equipment | DK6: Fixed livestock | DL6: Inventory stock | DM6: Total, aggregate economy | DN6: Total, private sector | DO6: Total, manufacturing and handicrafts | DQ6: Year | DR6: Residential buildings | DS6: Non-residential structures et al. | DT6: Machinery and equipment | DU6: Fixed livestock | DV6: Inventory stock | DW6: Total, aggregate economy | DX6: Total, private sector | DY6: Total, manufacturing and handicrafts | EA6: During year | EB6: Buildings and structures | EC6: Residential buildings | ED6: Non-residential structures et al. | EE6: Machinery and equipment | EF6: Fixed livestock | EG6: Inventory stock | EH6: Total, aggregate economy | EI6: Total, private sector | EJ6: Total, manufacturing and handicrafts | EL6: Year | EM6: Agriculture and ancillaries | EN6: Manufacturing and handicrafts | EO6: Building and construction | EP6: Transport and communication | EQ6: Circulation | ER6: Private reproductive services | ES6: Government services | ET6: Real estate | EU6: Total aggregate economy | EV6: Total private sector | EX6: Year | EY6: Agriculture and ancillaries | EZ6: Manufacturing and handicrafts | FA6: Building and construction | FB6: Transport and communication | FC6: Circulation | FD6: Private reproductive services | FE6: Government services | FF6: Real estate | FG6: Total aggregate economy | FH6: Total private sector | FJ6: Year | FK6: Agriculture and ancillaries | FL6: Manufacturing and handicrafts | FM6: Building and construction | FN6: Transport and communication | FO6: Circulation | FP6: Private reproductive services | FQ6: Real estate | FR6: Total number of self-employed | FS6: Number of “housewives” | FU6: Year | FV6: Agriculture and ancillaries | FW6: Manufacturing and handicrafts | FX6: Building and construction | FY6: Transport and communication | FZ6: Circulation | GA6: Private reproductive services | GB6: Government services | GC6: Real estate | GD6: Total aggregate economy | GE6: Total private sector | GG6: Year | GH6: Agriculture and ancillaries | GI6: Manufacturing and handicrafts | GJ6: Building and construction | GK6: Transport and communication | GL6: Circulation | GM6: Private reproductive services | GN6: Government services | GO6: Real estate | GP6: Total aggregate economy | GQ6: Private sector | GS6: Year | GT6: Agriculture and ancillaries | GU6: Manufacturing and handicrafts | GV6: Building and construction | GW6: Transport and communication | GX6: Circulation | GY6: Private reproductive services | GZ6: Real estate | HA6: Total aggregate economy | HC6: År | HD6: Agriculture and ancillaries | HE6: Manufacturing and handicrafts | HF6: Building and construction | HG6: Transport and communication | HH6: Other private services, here include circulation (code CC) and private reproductive services (code PR). | HI6: Government services | HJ6: Real estate | HK6: Total aggregate economy | HL6: Total private sector | HN6: Year | HO6: Agriculture and ancillaries | HP6: Manufacturing and handicrafts | HQ6: Building and construction | HR6: Transport and communication | HS6: Other private services, here include circulation (code CC) and private reproductive services (code PR). | HT6: Real estate | HU6: Total aggregate economy | HW6: Year | HX6: Agriculture and ancillaries | HY6: Manufacturing and handicrafts | HZ6: Building and construction | IA6: Transport and communication | IB6: Other private services, here include circulation (code CC) and private reproductive services | IC6: Government services | ID6: Real estate | IE6: Total aggregate economy | IF6: Total private sector | IH6: Year | II6: Net stock of produced assets/Gross value added | IJ6: Gross surplus/Labour income* | IK6: Gross surplus/Net stock of produced assets | IL6: Net stock of produced assets/Net value added | IM6: Net surplus/Labour income* | IN6: Net surplus/Net stock of produced assets | IO6: Change in annual real wage rate from previous year
A7: Årlig förändring | B7: Bruttonationalprodukt (BNP) från produktionssidan, Fischerindex, korrigerad för förändringar i förädlingsvärdets andel av bruttoprodukten, baserat på baspriser | C7: Nettonationalprodukt (NNP) från produktionssidan, Fisherindex, korrigerad för förändringar i förädlingsvärdets andel av bruttoprodukten, baserat på baspriser | D7: Bruttonationalprodukt (BNP) från produktionssidan, Laspeyres volymindex, korrigerad för förändringar i förädlingsvärdets andel av bruttoprodukten, baserat på baspriser | E7: Bruttonationalprodukt (BNP) från produktionssidan, Paasches volymindex, korrigerad för förändringar i förädlingsvärdets andel av bruttoprodukten, baserat på baspriser | F7: Bruttonationalprodukt (BNP) från produktionssidan, Fisherindex, okorrigerad för förändringar i förädlingsvärdets andel av bruttoprodukten, baserat på baspriser | G7: Bruttonationalprodukt (BNP) från användningssidan, Fisherindex, baserat på mottagarpriser | H7: Nettonationalprodukten (NNP) från användningssidan, Fisherindex, baserat på mottagarpriser | J7: År | K7: BNP från användningssidan, mottagarpris | L7: BNP från produktionssidan, mottagarpris | M7: NNP från användningssidan, mottagarpris | N7: NNP från produktionssidan, baspris | O7: Avskrivningar av fasta tillgångar, mottagarpris | P7: BNP till mottagarpris minus BNP till baspris | Q7: Insatsförbrukning, mottagarpris | R7: Bruttonationalproduktionsvärde, mottagarpris | S7: Bruttonationalproduktionsvärde, baspris | U7: År | V7: BNP per capita från användningssidan till mottagarpris (kronor), löpande värden | W7: BNP per capita från användningssidan till mottagarpris (kronor), volymvärde (referensår 2000) | X7: Volymtillväxt från föregående år (%) för BNP per capita från användningssidan till mottagarpris (kronor) | Y7: BNP per capita från produktionssidan till baspris (kronor), löpande värden | Z7: BNP per capita från produktionssidan till baspris (kronor), volymvärde (referensår 2000) | AA7: Volymtillväxt från föregående år (%) för BNP per capita från produktionssidan till baspris (kronor) | AB7: Medelfolkmängd | AC7: Befolkningstillväxt | AE7: År | AF7: Jordbruk med binäringar | AG7: Industri och hantverk | AH7: Byggnadsindustri | AI7: Transporter och kommunikationer | AJ7: Cirkulation | AK7: Privata reproduktiva tjänster | AL7: Offentliga tjänster | AM7: Fastighetsförvaltning | AN7: BNP från produktionssidan | AP7: Årlig förändring | AQ7: Jordbruk med binäringar | AR7: Industri och hantverk | AS7: Byggnadsindustri | AT7: Transporter och kommunikationer | AU7: Cirkulation | AV7: Privata reproduktiva tjänster | AW7: Offentliga tjänster | AX7: Fastighetsförvaltning | AY7: BNP | BA7: År | BB7: Privat konsumtion | BC7: Offentlig konsumtion | BD7: Investingar i byggnader och anläggningar | BE7: Investeringar i maskiner, transportmedel och inventarier | BF7: Förändring i fast djurstock | BG7: Lagerförändring | BH7: Export | BI7: Import | BJ7: BNP | BL7: Årlig förändring | BM7: Privat konsumtion | BN7: Offentlig konsumtion | BO7: Investeringar | BP7: Export | BQ7: Import | BR7: BNP | BT7: Årlig förändring | BU7: Privat konsumtion | BV7: Offentlig konsumtion | BW7: Investeringar | BX7: Export | BY7: Import | BZ7: BNP | CB7: År | CC7: Jordbruk med binäringar | CD7: Industri och hantverk | CE7: Byggnadsindustri | CF7: Transporter och kommunikationer | CG7: Övriga privata tjänster, här inkluderat cirkulation, privata reproduktiva tjänster och annan förvaltningsförvaltning | CH7: Offentliga tjänster | CI7: Bostadsförvaltning | CJ7: Totala bruttoinvesteringar | CL7: År | CM7: Jordbruk med binäringar | CN7: Industri och hantverk | CO7: Byggnadsindustri | CP7: Transporter och kommunikationer | CQ7: Övriga privata tjänster, här inkluderat cirkulation, privata reproduktiva tjänster och annan förvaltningsförvaltning | CR7: Offentliga tjänster | CS7: Bostadsförvaltning | CT7: Avskrivningar av fasta tillgångar, totalt | CV7: Year | CW7: Bostäder | CX7: Byggnader och anläggningar utom bostäder | CY7: Maskiner, transportmedel och inventarier | CZ7: Fast djurstock | DA7: Lagerstock | DB7: Totalt, hela ekonomin | DC7: Totalt, privat sektor | DD7: Totalt, industri och hantverk | DF7: Under loppet av år | DG7: Byggnader och anläggningar | DH7: Bostäder | DI7: Byggnader och anläggningar utom bostäder | DJ7: Maskiner, transportmedel och inventarier | DK7: Fast djurstock | DL7: Lagerstock | DM7: Totalt, hela ekonomin | DN7: Totalt, privat sektor | DO7: Totalt, industri och hantverk | DQ7: År | DR7: Bostäder | DS7: Byggnader och anläggningar utom bostäder | DT7: Maskiner, transportmedel och inventarier | DU7: Fast djurstock | DV7: Lagerstock | DW7: Totalt, hela ekonomin | DX7: Totalt, privat sektor | DY7: Totalt, industri och hantverk | EA7: Under loppet av år | EB7: Byggnader och anläggningar | EC7: Bostäder | ED7: Byggnader och anläggningar utom bostäder | EE7: Maskiner, transportmedel och inventarier | EF7: Fast djurstock | EG7: Lagerstock | EH7: Totalt, hela ekonomin | EI7: Totalt, privat sektor | EJ7: Totalt, industri och hantverk | EL7: År | EM7: Jordbruk med binäringar | EN7: Industri och hantverk | EO7: Byggnadsindustri | EP7: Transporter och kommunikationer | EQ7: Cirkulation | ER7: Privata reproduktiva tjänster | ES7: Offentliga tjänster | ET7: Fastighetsförvaltning | EU7: Totalt hela ekonomin | EV7: Totalt privat sektor | EX7: År | EY7: Jordbruk med binäringar | EZ7: Industri och hantverk | FA7: Byggnadsindustri | FB7: Transporter och kommunikationer | FC7: Cirkulation | FD7: Privata reproduktiva tjänster | FE7: Offentliga tjänster | FF7: Fastighetsförvaltning | FG7: Totalt hela ekonomin | FH7: Totalt privat sektor | FJ7: År | FK7: Jordbruk med binäringar | FL7: Industri och hantverk | FM7: Byggnadsindustri | FN7: Transporter och kommunikationer | FO7: Cirkulation | FP7: Privata reproduktiva tjänster | FQ7: Fastighetsförvaltning | FR7: Totalt antal företagare | FS7: Antal "hemmafruar" | FU7: År | FV7: Jordbruk med binäringar | FW7: Industri och hantverk | FX7: Byggnadsindustri | FY7: Transporter och kommunikationer | FZ7: Cirkulation | GA7: Privata reproduktiva tjänster | GB7: Offentliga tjänster | GC7: Fastighetsförvaltning | GD7: Totalt hela ekonomin | GE7: Totalt privat sektor | GG7: År | GH7: Jordbruk med binäringar | GI7: Industri och hantverk | GJ7: Byggnadsindustri | GK7: Transporter och kommunikationer | GL7: Cirkulation | GM7: Privata reproduktiva tjänster | GN7: Offentliga tjänster | GO7: Fastighetsförvaltning | GP7: Totalt hela ekonomin | GQ7: Totalt privat sektor | GS7: År | GT7: Jordbruk med binäringar | GU7: Industri och hantverk | GV7: Byggnadsindustri | GW7: Transporter och kommunikationer | GX7: Cirkulation | GY7: Privata reproduktiva tjänster | GZ7: Fastighetsförvaltning | HA7: Totalt hela ekonomin | HC7: Year | HD7: Jordbruk med binäringar | HE7: Industri och hantverk | HF7: Byggnadsindustri | HG7: Transporter och kommunikationer | HH7: Övriga privata tjänster, här inkluderat cirkulation och privata reproduktiva tjänster | HI7: Privata reproduktiva tjänster | HJ7: Fastighetsförvaltning | HK7: Totalt hela ekonomin | HL7: Totalt privat sektor | HN7: År | HO7: Jordbruk med binäringar | HP7: Industri och hantverk | HQ7: Byggnadsindustri | HR7: Transporter och kommunikationer | HS7: Övriga privata tjänster, här inkluderat cirkulation och privata reproduktiva tjänster | HT7: Fastighetsförvaltning | HU7: Totalt hela ekonomin | HW7: År | HX7: Jordbruk med binäringar | HY7: Industri och hantverk | HZ7: Byggnadsindustri | IA7: Transporter och kommunikationer | IB7: Övriga privata tjänster, här inkluderat cirkulation och privata reproduktiva tjänster | IC7: Offentliga tjänster | ID7: Fastighetsförvaltning | IE7: Totalt hela ekonomin | IF7: Totalt privat sektor | IH7: År | II7: Nettostock av producerade tillgångar/Bruttoförädlingsvärde | IJ7: Bruttoöverskott/Arbetsinkomst | IK7: Bruttoöverskott/Nettostock av producerade tillgångar | IL7: Nettostock av producerade tillgångar/nettoförädlingsvärde | IM7: Nettöverskott/Arbetsinkomst | IN7: Nettoöverskott/Nettostock av producerad tillgångar | IO7: Förändring av reallöne från föregående år
J8: 1800 | K8: 115.34355 | L8: 110.06013 | M8: 111.2225 | N8: 105.93908 | O8: 4.1210501 | P8: 5.283416 | Q8: 74.955499 | R8: 190.29905 | S8: 185.01563 | U8: 1800 | V8: 49.037642 | W8: 8598.1762 | Y8: 46.791428 | Z8: 7957.7299 | AB8: 2352143 | AE8: 1800 | AF8: 51.555396 | AG8: 12.085592 | AH8: 5.4648712 | AI8: 6.5083959 | AJ8: 4.0596346 | AK8: 14.438785 | AL8: 11.188284 | AM8: 4.759172 | AN8: 110.06013 | BA8: 1800 | BB8: 96.132772 | BC8: 13.271726 | BD8: 4.5935748 | BE8: 0.68449705 | BF8: 0.1197527 | BG8: 0.10492535 | BH8: 14.856538 | BI8: 14.42024 | BJ8: 115.34355 | CB8: 1800 | CC8: 2.1398109 | CD8: 1.0130101 | CE8: 0.017290177 | CF8: 0.63140524 | CG8: 0.30451597 | CH8: 0.19584581 | CI8: 1.2008717 | CJ8: 5.50275 | CL8: 1800 | CM8: 1.9275201 | CN8: 0.37002897 | CO8: 0.014241118 | CP8: 0.53382658 | CQ8: 0.097090435 | CR8: 0.13898309 | CS8: 1.0393598 | CT8: 4.1210501 | CV8: 1800 | CW8: 32.758354 | CX8: 56.115489 | CY8: 5.4337142 | CZ8: 17.39597 | DA8: 15.682366 | DB8: 127.38589 | DC8: 123.51326 | DD8: 18.613266 | DF8: 1800 | DG8: 1.3444966 | DH8: 0.49304034 | DI8: 1.8415483 | DJ8: -0.6861379 | DK8: 7.5105692 | DL8: 0.66906581 | DM8: 2.0120594 | DN8: 2.0288535 | DO8: 0.54484913 | DQ8: 1800 | DR8: 74.535614 | DS8: 131.26897 | DT8: 11.756553 | DU8: 17.39597 | DV8: 15.682366 | DW8: 250.63947 | DX8: 241.84453 | DY8: 28.239217 | EA8: 1800 | EB8: 0.93453894 | EC8: 0.55666312 | ED8: 1.1491 | EE8: -0.078224647 | EF8: 7.5105692 | EG8: 0.66906581 | EH8: 1.3265804 | EI8: 1.3384896 | EJ8: 0.62252243
A9: 1800-1801 | B9: -4.4491681 | C9: -4.4335349 | D9: -3.8903594 | E9: -5.0047277 | F9: -4.4543026 | G9: -7.2386294 | H9: -7.5304379 | J9: 1801 | K9: 118.16873 | L9: 112.73241 | M9: 114.03639 | N9: 108.60007 | O9: 4.1323416 | P9: 5.4363206 | Q9: 79.320786 | R9: 197.48951 | S9: 192.05319 | U9: 1801 | V9: 50.260518 | W9: 7979.2416 | X9: -7.1984407 | Y9: 47.948296 | Z9: 7606.9714 | AA9: -4.4077708 | AB9: 2351124.4 | AC9: -0.043306069 | AE9: 1801 | AF9: 52.345831 | AG9: 12.777799 | AH9: 5.4206768 | AI9: 6.958832 | AJ9: 5.0812015 | AK9: 14.204542 | AL9: 10.999162 | AM9: 4.9443638 | AN9: 112.73241 | AP9: 1800-1801 | AQ9: -9.9971455 | AR9: 2.4438345 | AS9: -0.1617398 | AT9: -1.9966428 | AU9: -2.4152357 | AV9: 0.33584003 | AW9: 2.8294944 | AX9: 0.40497629 | AY9: -4.4491681 | BA9: 1801 | BB9: 99.153551 | BC9: 12.586415 | BD9: 4.6332199 | BE9: 0.74393477 | BF9: -0.30646626 | BG9: 0.15100382 | BH9: 19.653271 | BI9: 18.446201 | BJ9: 118.16873 | BL9: 1800-1801 | BM9: -9.320104 | BN9: -1.3922634 | BO9: -4.8820506 | BP9: 32.542291 | BQ9: 24.489116 | BR9: -7.2386294 | BT9: 1800-1801 | BU9: 13.743292 | BV9: -3.8246777 | BW9: -0.23711215 | BX9: -0.1925976 | BY9: 2.7550244 | BZ9: 10.443995 | CB9: 1801 | CC9: 1.8577282 | CD9: 0.93476082 | CE9: 0.016674194 | CF9: 0.69684498 | CG9: 0.28420025 | CH9: 0.16353982 | CI9: 1.2679439 | CJ9: 5.2216922 | CL9: 1801 | CM9: 1.9202824 | CN9: 0.37386969 | CO9: 0.012115157 | CP9: 0.54165006 | CQ9: 0.10221098 | CR9: 0.13609164 | CS9: 1.0461217 | CT9: 4.1323416 | CV9: 1801 | CW9: 32.919866 | CX9: 57.148883 | CY9: 5.1304917 | CZ9: 18.702506 | DA9: 17.23174 | DB9: 131.13349 | DC9: 127.2326 | DD9: 19.641014 | DF9: 1801 | DG9: 1.3231269 | DH9: 0.6738249 | DI9: 1.6971488 | DJ9: 1.0255197 | DK9: 1.618629 | DL9: 0.87631205 | DM9: 1.2948809 | DN9: 1.3130513 | DO9: 0.35534152 | DQ9: 1801 | DR9: 74.950526 | DS9: 132.77738 | DT9: 11.167818 | DU9: 18.702506 | DV9: 17.23174 | DW9: 254.82997 | DX9: 246.00939 | DY9: 29.227788 | EA9: 1801 | EB9: 0.936933 | EC9: 0.63691845 | ED9: 1.106286 | EE9: 0.73706048 | EF9: 1.618629 | EG9: 0.87631205 | EH9: 0.97400773 | EI9: 0.9852661 | EJ9: 0.54432545
A10: 1801-1802 | B10: 3.8116577 | C10: 3.8350712 | D10: 3.8207195 | E10: 3.8025968 | F10: 3.6531445 | G10: 4.215858 | H10: 4.3608909 | J10: 1802 | K10: 121.16509 | L10: 115.5673 | M10: 117.0088 | N10: 111.411 | O10: 4.1562936 | P10: 5.5977949 | Q10: 79.517196 | R10: 200.68229 | S10: 195.08449 | U10: 1802 | V10: 51.263632 | W10: 8271.8545 | X10: 3.6671765 | Y10: 48.895266 | Z10: 7855.347 | AA10: 3.2651042 | AB10: 2363568.2 | AC10: 0.52927222 | AE10: 1802 | AF10: 54.244934 | AG10: 13.231086 | AH10: 4.2322086 | AI10: 8.3508132 | AJ10: 6.0039647 | AK10: 13.718799 | AL10: 10.812283 | AM10: 4.9732088 | AN10: 115.5673 | AP10: 1801-1802 | AQ10: 4.4764961 | AR10: 8.9970555 | AS10: -16.975263 | AT10: 13.134129 | AU10: 4.3902316 | AV10: 0.5993191 | AW10: 3.8626133 | AX10: 0.583392 | AY10: 3.8116577 | BA10: 1802 | BB10: 96.614661 | BC10: 12.593731 | BD10: 3.6872652 | BE10: 0.66018231 | BF10: 0.26340701 | BG10: 0.46432797 | BH10: 20.975206 | BI10: 14.093688 | BJ10: 121.16509 | BL10: 1801-1802 | BM10: 0.19039309 | BN10: 4.486049 | BO10: -3.0054466 | BP10: 8.5008206 | BQ10: -15.429566 | BR10: 4.215858 | BT10: 1801-1802 | BU10: -2.7457294 | BV10: -4.2378117 | BW10: 0.20584198 | BX10: -1.6355067 | BY10: -9.6560301 | BZ10: -1.612224 | CB10: 1802 | CC10: 1.9532286 | CD10: 0.96621727 | CE10: 0.014835421 | CF10: 0.64641938 | CG10: 0.32308318 | CH10: 0.18124536 | CI10: 0.99015324 | CJ10: 5.0751824 | CL10: 1802 | CM10: 1.9118291 | CN10: 0.39241432 | CO10: 0.013777404 | CP10: 0.54723776 | CQ10: 0.10537096 | CR10: 0.13985094 | CS10: 1.0458131 | CT10: 4.1562936 | CV10: 1802 | CW10: 33.141688 | CX10: 58.118784 | CY10: 5.2863428 | CZ10: 19.00523 | DA10: 17.33489 | DB10: 132.88694 | DC10: 128.93975 | DD10: 19.741995 | DF10: 1802 | DG10: 0.25599633 | DH10: -0.16794503 | DI10: 0.49774489 | DJ10: -0.77105175 | DK10: -0.95177444 | DL10: 2.6785746 | DM10: 0.35936906 | DN10: 0.33841929 | DO10: 4.5163723 | DQ10: 1802 | DR10: 75.4279 | DS10: 134.24628 | DT10: 11.476398 | DU10: 19.00523 | DV10: 17.33489 | DW10: 257.49069 | DX10: 248.57107 | DY10: 29.493088 | EA10: 1802 | EB10: 0.46905091 | EC10: 0.25839648 | ED10: 0.58740967 | EE10: -0.13820485 | EF10: -0.95177444 | EG10: 2.6785746 | EH10: 0.4858655 | EI10: 0.4740072 | EJ10: 3.3581454
A11: 1802-1803 | B11: 0.54520004 | C11: 0.53786318 | D11: 0.59366603 | E11: 0.49675739 | F11: 0.60106744 | G11: -2.036769 | H11: -2.1067364 | J11: 1803 | K11: 115.42132 | L11: 110.11268 | M11: 111.34106 | N11: 106.03243 | O11: 4.0802559 | P11: 5.3086319 | Q11: 79.093535 | R11: 194.51485 | S11: 189.20622 | U11: 1803 | V11: 48.488133 | W11: 8046.0657 | X11: -2.7296029 | Y11: 46.257994 | Z11: 7842.3154 | AA11: -0.16589452 | AB11: 2380403.4 | AC11: 0.71227618 | AE11: 1803 | AF11: 50.48202 | AG11: 13.325406 | AH11: 3.8449263 | AI11: 8.0128928 | AJ11: 5.4958477 | AK11: 12.694969 | AL11: 10.768957 | AM11: 5.4876647 | AN11: 110.11268 | AP11: 1802-1803 | AQ11: 0.54345474 | AR11: -1.8008398 | AS11: -1.7714022 | AT11: 2.3790326 | AU11: -4.4416055 | AV11: 0.41328979 | AW11: 6.159575 | AX11: 0.25205644 | AY11: 0.54520004 | BA11: 1803 | BB11: 91.646348 | BC11: 12.97674 | BD11: 3.4496478 | BE11: 0.65168502 | BF11: 0.14462245 | BG11: 0.42727941 | BH11: 19.550888 | BI11: 13.425896 | BJ11: 115.42132 | BL11: 1802-1803 | BM11: -1.8554296 | BN11: 8.0943768 | BO11: -6.6744678 | BP11: -9.7286425 | BQ11: -5.2639907 | BR11: -2.036769 | BT11: 1802-1803 | BU11: -3.349111 | BV11: -4.6747181 | BW11: -1.3344697 | BX11: 3.2548113 | BY11: 0.55496968 | BZ11: -2.7598984 | CB11: 1803 | CC11: 2.0377381 | CD11: 0.43800253 | CE11: 0.013201321 | CF11: 0.68410895 | CG11: 0.1388221 | CH11: 0.21722182 | CI11: 1.1441398 | CJ11: 4.6732347 | CL11: 1803 | CM11: 1.8602901 | CN11: 0.38608181 | CO11: 0.015778332 | CP11: 0.55939311 | CQ11: 0.099677337 | CR11: 0.14170477 | CS11: 1.0173305 | CT11: 4.0802559 | CV11: 1803 | CW11: 32.05209 | CX11: 56.582815 | CY11: 5.5078367 | CZ11: 18.824343 | DA11: 17.904556 | DB11: 130.87164 | DC11: 126.9768 | DD11: 20.545481 | DF11: 1803 | DG11: 0.11180572 | DH11: 0.39563519 | DI11: -0.048973272 | DJ11: -1.4241483 | DK11: 0.71111816 | DL11: 2.3864284 | DM11: 0.42799843 | DN11: 0.38103634 | DO11: 2.8292946 | DQ11: 1803 | DR11: 73.25959 | DS11: 130.81501 | DT11: 12.023952 | DU11: 18.824343 | DV11: 17.904556 | DW11: 252.82745 | DX11: 244.0489 | DY11: 30.209509 | EA11: 1803 | EB11: 0.39916236 | EC11: 0.50412877 | ED11: 0.34037862 | EE11: -0.50620509 | EF11: 0.71111816 | EG11: 2.3864284 | EH11: 0.51210681 | EI11: 0.48618114 | EJ11: 2.1920761
A12: 1803-1804 | B12: -0.73621898 | C12: -0.79674509 | D12: -0.65777754 | E12: -0.81459847 | F12: -0.71394539 | G12: 1.4880478 | H12: 1.5183574 | J12: 1804 | K12: 113.90068 | L12: 108.6599 | M12: 109.53418 | N12: 104.29341 | O12: 4.3664952 | P12: 5.2407738 | Q12: 77.285617 | R12: 191.18629 | S12: 185.94552 | U12: 1804 | V12: 47.533789 | W12: 8111.948 | X12: 0.81881397 | Y12: 45.346674 | Z12: 7733.2456 | AA12: -1.3907856 | AB12: 2396204.5 | AC12: 0.6637986 | AE12: 1804 | AF12: 49.014837 | AG12: 13.251897 | AH12: 4.5688065 | AI12: 7.7605126 | AJ12: 4.6887319 | AK12: 13.127684 | AL12: 10.586047 | AM12: 5.661387 | AN12: 108.6599 | AP12: 1803-1804 | AQ12: -1.4129765 | AR12: 0.12834235 | AS12: 5.7492289 | AT12: 0.4349827 | AU12: 3.3982293 | AV12: 0.46922564 | AW12: -5.6758731 | AX12: 0.1134485 | AY12: -0.73621898 | BA12: 1804 | BB12: 101.01626 | BC12: 12.529314 | BD12: 4.2006047 | BE12: 0.8687678 | BF12: 0.096287749 | BG12: -0.021057463 | BH12: 17.993398 | BI12: 22.782894 | BJ12: 113.90068 | BL12: 1803-1804 | BM12: 14.736282 | BN12: -6.1538488 | BO12: 4.7053363 | BP12: -9.7067556 | BQ12: 66.811425 | BR12: 1.4880478 | BT12: 1803-1804 | BU12: -3.9327567 | BV12: 2.8833786 | BW12: 5.1393887 | BX12: 1.9275138 | BY12: 1.727837 | BZ12: -2.7643808 | CB12: 1804 | CC12: 2.1174354 | CD12: 0.74143034 | CE12: 0.017680421 | CF12: 0.72025202 | CG12: 0.20006912 | CH12: 0.19605011 | CI12: 1.1516854 | CJ12: 5.1446028 | CL12: 1804 | CM12: 1.9818879 | CN12: 0.42344341 | CO12: 0.016598665 | CP12: 0.59775071 | CQ12: 0.10942079 | CR12: 0.15163646 | CS12: 1.0857573 | CT12: 4.3664952 | CV12: 1804 | CW12: 34.254957 | CX12: 60.203821 | CY12: 5.7328449 | CZ12: 18.958207 | DA12: 17.266884 | DB12: 136.41671 | DC12: 132.19214 | DD12: 20.912827 | DF12: 1804 | DG12: 0.64646844 | DH12: 0.1924632 | DI12: 0.90478975 | DJ12: 1.6148775 | DK12: 20.564132 | DL12: -0.12195288 | DM12: 3.289348 | DN12: 3.3612454 | DO12: -0.76711115 | DQ12: 1804 | DR12: 78.379165 | DS12: 139.72868 | DT12: 12.635333 | DU12: 18.958207 | DV12: 17.266884 | DW12: 266.96827 | DX12: 257.51284 | DY12: 31.283189 | EA12: 1804 | EB12: 0.63222765 | EC12: 0.4109118 | ED12: 0.75637218 | EE12: 0.93464888 | EF12: 20.564132 | EG12: -0.12195288 | EH12: 1.9757539 | EI12: 2.0177076 | EJ12: -0.18497081
A13: 1804-1805 | B13: 4.4854784 | C13: 4.4786817 | D13: 4.3964206 | E13: 4.5746122 | F13: 4.3954423 | G13: 3.9505492 | H13: 4.1040377 | J13: 1805 | K13: 123.81956 | L13: 118.09243 | M13: 119.19893 | N13: 113.47179 | O13: 4.6206345 | P13: 5.7271369 | Q13: 82.128975 | R13: 205.94854 | S13: 200.2214 | U13: 1805 | V13: 51.315466 | W13: 8374.036 | X13: 3.2308881 | Y13: 48.941926 | Z13: 8024.1791 | AA13: 3.7621139 | AB13: 2412909.3 | AC13: 0.6971374 | AE13: 1805 | AF13: 55.788233 | AG13: 14.211373 | AH13: 4.5485506 | AI13: 7.7699051 | AJ13: 5.7796913 | AK13: 13.265296 | AL13: 10.916955 | AM13: 5.8124226 | AN13: 118.09243 | AP13: 1804-1805 | AQ13: 7.7020785 | AR13: 4.7651023 | AS13: -5.7852275 | AT13: -1.9234834 | AU13: 5.1128511 | AV13: 0.80379541 | AW13: 4.6680146 | AX13: 0.29399775 | AY13: 4.4854784 | BA13: 1805 | BB13: 105.32606 | BC13: 12.806465 | BD13: 3.97771 | BE13: 0.74440617 | BF13: 0.34292829 | BG13: 0.34099196 | BH13: 17.216482 | BI13: 16.935476 | BJ13: 123.81956 | BL13: 1804-1805 | BM13: 0.67885697 | BN13: 3.0151388 | BO13: -0.41584769 | BP13: -6.1104551 | BQ13: -21.057375 | BR13: 3.9505492 | BT13: 1804-1805 | BU13: 3.5633966 | BV13: -0.77961176 | BW13: 5.5205096 | BX13: 1.9093386 | BY13: -5.8377194 | BZ13: 4.5769998 | CB13: 1805 | CC13: 2.5425138 | CD13: 0.57332995 | CE13: 0.015673921 | CF13: 0.63140187 | CG13: 0.16265468 | CH13: 0.19854483 | CI13: 1.2819173 | CJ13: 5.4060364 | CL13: 1805 | CM13: 2.0929489 | CN13: 0.44978827 | CO13: 0.017720184 | CP13: 0.62765877 | CQ13: 0.11475511 | CR13: 0.16187644 | CS13: 1.1558868 | CT13: 4.6206345 | CV13: 1805 | CW13: 36.400939 | CX13: 64.430269 | CY13: 6.0589182 | CZ13: 22.856797 | DA13: 18.319924 | DB13: 148.06685 | DC13: 143.53591 | DD13: 22.041614 | DF13: 1805 | DG13: 0.16100987 | DH13: 0.34622857 | DI13: 0.056367523 | DJ13: -1.0187783 | DK13: -14.471073 | DL13: 1.8613175 | DM13: -1.8980907 | DN13: -1.983461 | DO13: -2.4553285 | DQ13: 1805 | DR13: 83.471006 | DS13: 149.31801 | DT13: 13.257894 | DU13: 22.856797 | DV13: 18.319924 | DW13: 287.22363 | DX13: 277.10411 | DY13: 33.162583 | EA13: 1805 | EB13: 0.41544008 | EC13: 0.47560212 | ED13: 0.3818086 | EE13: -0.31905701 | EF13: -14.471073 | EG13: 1.8613175 | EH13: -0.69190956 | EI13: -0.74369292 | EJ13: -1.3252687
A14: 1805-1806 | B14: 0.22097275 | C14: 0.23323719 | D14: 0.39072939 | E14: 0.051503164 | F14: 0.32879509 | G14: 1.8260137 | H14: 1.8835622 | J14: 1806 | K14: 133.09498 | L14: 126.96119 | M14: 128.30897 | N14: 122.17517 | O14: 4.7860178 | P14: 6.1337931 | Q14: 86.999202 | R14: 220.09419 | S14: 213.96039 | U14: 1806 | V14: 54.875835 | W14: 8483.0889 | X14: 1.3022744 | Y14: 52.346837 | Z14: 8000.547 | AA14: -0.29451106 | AB14: 2425384.2 | AC14: 0.51700645 | AE14: 1806 | AF14: 57.752563 | AG14: 14.762946 | AH14: 4.8523967 | AI14: 7.3204265 | AJ14: 7.1579355 | AK14: 16.605811 | AL14: 12.175709 | AM14: 6.333401 | AN14: 126.96119 | AP14: 1805-1806 | AQ14: 2.3905305 | AR14: 1.1883697 | AS14: -0.74151889 | AT14: -1.6657567 | AU14: 4.1275531 | AV14: -0.14326326 | AW14: -10.926473 | AX14: 0.26931641 | AY14: 0.22097275 | BA14: 1806 | BB14: 112.45945 | BC14: 14.228689 | BD14: 4.1236722 | BE14: 0.96032168 | BF14: 0.075861617 | BG14: 0.49781952 | BH14: 19.140004 | BI14: 18.390834 | BJ14: 133.09498 | BL14: 1805-1806 | BM14: 0.80916135 | BN14: -7.7089432 | BO14: 0.94481162 | BP14: 9.6209823 | BQ14: -4.56621 | BR14: 1.8260137 | BT14: 1805-1806 | BU14: 5.9156462 | BV14: 20.386 | BW14: 3.6752354 | BX14: 1.4154079 | BY14: 13.789405 | BZ14: 5.5634735 | CB14: 1806 | CC14: 2.6491551 | CD14: 0.48668427 | CE14: 0.012948422 | CF14: 0.70283536 | CG14: 0.16670867 | CH14: 0.21629477 | CI14: 1.4230484 | CJ14: 5.657675 | CL14: 1806 | CM14: 2.1814311 | CN14: 0.45486739 | CO14: 0.017943038 | CP14: 0.65346131 | CQ14: 0.11472135 | CR14: 0.16770756 | CS14: 1.1958861 | CT14: 4.7860178 | CV14: 1806 | CW14: 37.570597 | CX14: 66.308489 | CY14: 6.3028723 | CZ14: 19.549173 | DA14: 20.038278 | DB14: 149.76941 | DC14: 145.07015 | DD14: 22.670218 | DF14: 1806 | DG14: 0.18460499 | DH14: 0.60462782 | DI14: -0.053381255 | DJ14: 1.6508045 | DK14: 4.1498752 | DL14: 2.4843428 | DM14: 1.0746236 | DN14: 1.0759068 | DO14: -0.56561103 | DQ14: 1806 | DR14: 86.264225 | DS14: 154.17064 | DT14: 13.884994 | DU14: 19.549173 | DV14: 20.038278 | DW14: 293.90731 | DX14: 283.42036 | DY14: 34.221646 | EA14: 1806 | EB14: 0.41966077 | EC14: 0.58845194 | ED14: 0.32521581 | EE14: 0.95121459 | EF14: 4.1498752 | EG14: 2.4843428 | EH14: 0.83550037 | EI14: 0.83565413 | EJ14: -0.095044134
A15: 1806-1807 | B15: -3.1828525 | C15: -3.1532172 | D15: -3.0979268 | E15: -3.2677038 | F15: -3.1571691 | G15: -4.1642941 | H15: -4.3307297 | J15: 1807 | K15: 139.55179 | L15: 133.09089 | M15: 134.74757 | N15: 128.28666 | O15: 4.8042269 | P15: 6.4609074 | Q15: 90.247446 | R15: 229.79924 | S15: 223.33833 | U15: 1807 | V15: 57.330565 | W15: 8100.5164 | X15: -4.5098251 | Y15: 54.6763 | Z15: 7717.9739 | AA15: -3.5319221 | AB15: 2434160.4 | AC15: 0.36184981 | AE15: 1807 | AF15: 64.293654 | AG15: 14.283501 | AH15: 5.3546157 | AI15: 6.8757699 | AJ15: 7.2426229 | AK15: 16.493305 | AL15: 12.183912 | AM15: 6.3635065 | AN15: 133.09089 | AP15: 1806-1807 | AQ15: -4.0958874 | AR15: -6.2882234 | AS15: 7.1576191 | AT15: -11.47493 | AU15: -2.5633516 | AV15: -0.052391245 | AW15: -0.26931135 | AX15: 0.47534513 | AY15: -3.1828525 | BA15: 1807 | BB15: 115.02678 | BC15: 14.126976 | BD15: 4.5276759 | BE15: 0.87061585 | BF15: 0.00026067057 | BG15: -0.0073600777 | BH15: 18.723132 | BI15: 13.71629 | BJ15: 139.55179 | BL15: 1806-1807 | BM15: -7.6549492 | BN15: -0.51042736 | BO15: -4.7709421 | BP15: -3.1392918 | BQ15: -23.165869 | BR15: -4.1642941 | BT15: 1806-1807 | BU15: 10.761645 | BV15: -0.20546131 | BW15: 0.063881068 | BX15: 0.99243281 | BY15: -2.93089 | BZ15: 9.4073232 | CB15: 1807 | CC15: 2.8245608 | CD15: 0.11611579 | CE15: 0.013470019 | CF15: 0.65347018 | CG15: 0.01494128 | CH15: 0.21060313 | CI15: 1.5580311 | CJ15: 5.3911923 | CL15: 1807 | CM15: 2.2073528 | CN15: 0.44100763 | CO15: 0.017294099 | CP15: 0.65275707 | CQ15: 0.11147552 | CR15: 0.16819637 | CS15: 1.2061434 | CT15: 4.8042269 | CV15: 1807 | CW15: 37.79776 | CX15: 66.273093 | CY15: 6.3581318 | CZ15: 20.36044 | DA15: 21.217493 | DB15: 152.00692 | DC15: 147.26269 | DD15: 22.961144 | DF15: 1807 | DG15: 0.55340011 | DH15: 0.93097518 | DI15: 0.33805642 | DJ15: 0.26804565 | DK15: -37.7265 | DL15: -0.034688724 | DM15: -6.0366479 | DN15: -6.2498765 | DO15: -6.8041973 | DQ15: 1807 | DR15: 86.771848 | DS15: 154.67202 | DT15: 13.906691 | DU15: 20.36044 | DV15: 21.217493 | DW15: 296.9285 | DX15: 286.3626 | DY15: 34.593418 | EA15: 1807 | EB15: 0.57768035 | EC15: 0.73442308 | ED15: 0.48974683 | EE15: 0.31184158 | EF15: -37.7265 | EG15: -0.034688724 | EH15: -2.8794724 | EI15: -3.0109072 | EJ15: -4.2611095
A16: 1807-1808 | B16: -3.6381447 | C16: -3.6703096 | D16: -3.265078 | E16: -4.0097726 | F16: -3.5664494 | G16: -2.3922435 | H16: -2.5124802 | J16: 1808 | K16: 155.54693 | L16: 148.4229 | M16: 149.8509 | N16: 142.72687 | O16: 5.6960355 | P16: 7.1240305 | Q16: 95.133185 | R16: 250.68012 | S16: 243.55609 | U16: 1808 | V16: 63.916705 | W16: 7908.5919 | X16: -2.3692876 | Y16: 60.989328 | Z16: 7438.932 | AA16: -3.6154819 | AB16: 2433588.1 | AC16: -0.023512955 | AE16: 1808 | AF16: 69.046519 | AG16: 14.428377 | AH16: 7.3918545 | AI16: 4.6694123 | AJ16: 9.5817332 | AK16: 20.660584 | AL16: 15.106492 | AM16: 7.5379305 | AN16: 148.4229 | AP16: 1807-1808 | AQ16: -3.8337799 | AR16: -3.2653488 | AS16: 8.7339193 | AT16: -26.966392 | AU16: -2.5916916 | AV16: -0.52345618 | AW16: -4.2872078 | AX16: 0.76766939 | AY16: -3.6381447 | BA16: 1808 | BB16: 133.10257 | BC16: 17.744 | BD16: 5.8886895 | BE16: 1.0014946 | BF16: 0.22397474 | BG16: -0.42693092 | BH16: 11.918126 | BI16: 13.904989 | BJ16: 155.54693 | BL16: 1807-1808 | BM16: 4.5655455 | BN16: -0.96498896 | BO16: 4.6553456 | BP16: -44.717499 | BQ16: 1.7067405 | BR16: -2.3922435 | BT16: 1807-1808 | BU16: 10.662087 | BV16: 26.827539 | BW16: 18.522249 | BX16: 15.14412 | BY16: -0.32545469 | BZ16: 14.193582 | CB16: 1808 | CC16: 4.2914451 | CD16: -0.10991862 | CE16: 0.018358239 | CF16: 0.2568059 | CG16: -0.13350885 | CH16: 0.072133467 | CI16: 2.2919127 | CJ16: 6.6872279 | CL16: 1808 | CM16: 2.6564334 | CN16: 0.47684348 | CO16: 0.013460463 | CP16: 0.73028428 | CQ16: 0.13236163 | CR16: 0.19043194 | CS16: 1.4962203 | CT16: 5.6960355 | CV16: 1808 | CW16: 46.627347 | CX16: 81.274274 | CY16: 6.099912 | CZ16: 25.358317 | DA16: 24.351919 | DB16: 183.71177 | DC16: 177.95708 | DD16: 24.857476 | DF16: 1808 | DG16: 0.80104748 | DH16: 1.7064929 | DI16: 0.28159013 | DJ16: 2.8419433 | DK16: 6.6485088 | DL16: -1.7531716 | DM16: 1.4825461 | DN16: 1.5951739 | DO16: 3.0285666 | DQ16: 1808 | DR16: 106.83337 | DS16: 189.96942 | DT16: 13.359007 | DU16: 25.358317 | DV16: 24.351919 | DW16: 359.87203 | DX16: 347.0762 | DY16: 38.744911 | EA16: 1808 | EB16: 0.68618351 | EC16: 1.0856506 | ED16: 0.46153467 | EE16: 1.5834576 | EF16: 6.6485088 | EG16: -1.7531716 | EH16: 1.0528887 | EI16: 1.1124051 | EJ16: 2.1428877
A17: 1808-1809 | B17: -4.1354473 | C17: -4.1767353 | D17: -3.9745721 | E17: -4.296053 | F17: -4.2806174 | G17: 0.7588384 | H17: 0.77953293 | J17: 1809 | K17: 166.61586 | L17: 158.74449 | M17: 160.28759 | N17: 152.41622 | O17: 6.3282705 | P17: 7.8713742 | Q17: 100.38571 | R17: 267.00157 | S17: 259.1302 | U17: 1809 | V17: 69.112604 | W17: 8043.9675 | X17: 1.7117535 | Y17: 65.847542 | Z17: 7198.7423 | AA17: -3.2288194 | AB17: 2410788.3 | AC17: -0.93687802 | AE17: 1809 | AF17: 82.278618 | AG17: 14.966813 | AH17: 7.3202909 | AI17: 9.015166 | AJ17: 7.8741226 | AK17: 17.51847 | AL17: 11.442569 | AM17: 8.3284364 | AN17: 158.74449 | AP17: 1808-1809 | AQ17: -6.5924155 | AR17: -5.5014134 | AS17: -10.508543 | AT17: 26.042963 | AU17: -1.2463791 | AV17: -0.68578139 | AW17: -7.6275635 | AX17: 1.3179921 | AY17: -4.1354473 | BA17: 1809 | BB17: 149.074 | BC17: 13.303649 | BD17: 5.3741267 | BE17: 0.9554115 | BF17: -0.20687607 | BG17: -0.31225504 | BH17: 20.845734 | BI17: 22.417925 | BJ17: 166.61586 | BL17: 1808-1809 | BM17: 1.1910215 | BN17: -15.335023 | BO17: -22.882588 | BP17: 76.546956 | BQ17: 35.1834 | BR17: 0.7588384 | BT17: 1808-1809 | BU17: 10.681103 | BV17: -11.444522 | BW17: 12.669919 | BX17: -0.92843802 | BY17: 19.261808 | BZ17: 6.3094171 | CB17: 1809 | CC17: 3.2492654 | CD17: 0.13245069 | CE17: 0.018643174 | CF17: 0.34507331 | CG17: -0.0081618364 | CH17: 0.064324157 | CI17: 2.0088122 | CJ17: 5.8104071 | CL17: 1809 | CM17: 2.9858766 | CN17: 0.52136856 | CO17: 0.015108656 | CP17: 0.77545469 | CQ17: 0.14546692 | CR17: 0.20814014 | CS17: 1.6768549 | CT17: 6.3282705 | CV17: 1809 | CW17: 52.812021 | CX17: 90.764854 | CY17: 6.7735018 | CZ17: 40.566401 | DA17: 23.582802 | DB17: 214.49958 | DC17: 208.22867 | DD17: 26.583412 | DF17: 1809 | DG17: -0.031527877 | DH17: 0.62856384 | DI17: -0.41560581 | DJ17: 0.70707622 | DK17: 26.191916 | DL17: -1.3240795 | DM17: 4.5641405 | DN17: 4.7751696 | DO17: -0.051230545 | DQ17: 1809 | DR17: 120.26516 | DS17: 212.53326 | DT17: 14.643308 | DU17: 40.566401 | DV17: 23.582802 | DW17: 411.59094 | DX17: 397.43577 | DY17: 42.117928 | EA17: 1809 | EB17: 0.31795871 | EC17: 0.61555495 | ED17: 0.14955938 | EE17: 0.62276405 | EF17: 26.191916 | EG17: -1.3240795 | EH17: 2.6378085 | EI17: 2.7578038 | EJ17: 0.17413016
